{
  "version": 8,
  "blockIdVersion": 11,
  "anchorX": 5,
  "anchorY": 0,
  "anchorZ": 5,
  "blocks": [
    {
      "x": -5,
      "y": -2,
      "z": -2,
      "name": "Soil_Dirt"
    },
    {
      "x": -5,
      "y": -1,
      "z": -2,
      "name": "Soil_Dirt"
    },
    {
      "x": -5,
      "y": 0,
      "z": -2,
      "name": "Soil_Grass"
    },
    {
      "x": -5,
      "y": 1,
      "z": -2,
      "name": "Empty"
    },
    {
      "x": -5,
      "y": 2,
      "z": -2,
      "name": "Empty"
    },
    {
      "x": -5,
      "y": 3,
      "z": -2,
      "name": "Empty"
    },
    {
      "x": -5,
      "y": 4,
      "z": -2,
      "name": "Empty"
    },
    {
      "x": -5,
      "y": -2,
      "z": -1,
      "name": "Soil_Dirt"
    },
    {
      "x": -5,
      "y": -1,
      "z": -1,
      "name": "Soil_Dirt"
    },
    {
      "x": -5,
      "y": 0,
      "z": -1,
      "name": "Soil_Grass"
    },
    {
      "x": -5,
      "y": 1,
      "z": -1,
      "name": "Empty"
    },
    {
      "x": -5,
      "y": 2,
      "z": -1,
      "name": "Empty"
    },
    {
      "x": -5,
      "y": 3,
      "z": -1,
      "name": "Empty"
    },
    {
      "x": -5,
      "y": 4,
      "z": -1,
      "name": "Empty"
    },
    {
      "x": -5,
      "y": -2,
      "z": 0,
      "name": "Soil_Dirt"
    },
    {
      "x": -5,
      "y": -1,
      "z": 0,
      "name": "Soil_Dirt"
    },
    {
      "x": -5,
      "y": 0,
      "z": 0,
      "name": "Soil_Grass"
    },
    {
      "x": -5,
      "y": 1,
      "z": 0,
      "name": "Empty"
    },
    {
      "x": -5,
      "y": 2,
      "z": 0,
      "name": "Empty"
    },
    {
      "x": -5,
      "y": 3,
      "z": 0,
      "name": "Empty"
    },
    {
      "x": -5,
      "y": 4,
      "z": 0,
      "name": "Empty"
    },
    {
      "x": -5,
      "y": -2,
      "z": 1,
      "name": "Soil_Dirt"
    },
    {
      "x": -5,
      "y": -1,
      "z": 1,
      "name": "Soil_Dirt"
    },
    {
      "x": -5,
      "y": 0,
      "z": 1,
      "name": "Soil_Grass"
    },
    {
      "x": -5,
      "y": 1,
      "z": 1,
      "name": "Empty"
    },
    {
      "x": -5,
      "y": 2,
      "z": 1,
      "name": "Empty"
    },
    {
      "x": -5,
      "y": 3,
      "z": 1,
      "name": "Empty"
    },
    {
      "x": -5,
      "y": 4,
      "z": 1,
      "name": "Empty"
    },
    {
      "x": -5,
      "y": -2,
      "z": 2,
      "name": "Soil_Dirt"
    },
    {
      "x": -5,
      "y": -1,
      "z": 2,
      "name": "Soil_Dirt"
    },
    {
      "x": -5,
      "y": 0,
      "z": 2,
      "name": "Soil_Grass"
    },
    {
      "x": -5,
      "y": 1,
      "z": 2,
      "name": "Empty"
    },
    {
      "x": -5,
      "y": 2,
      "z": 2,
      "name": "Empty"
    },
    {
      "x": -5,
      "y": 3,
      "z": 2,
      "name": "Empty"
    },
    {
      "x": -5,
      "y": 4,
      "z": 2,
      "name": "Empty"
    },
    {
      "x": -5,
      "y": -2,
      "z": 3,
      "name": "Soil_Dirt"
    },
    {
      "x": -5,
      "y": -1,
      "z": 3,
      "name": "Soil_Dirt"
    },
    {
      "x": -5,
      "y": 0,
      "z": 3,
      "name": "Soil_Grass"
    },
    {
      "x": -5,
      "y": 1,
      "z": 3,
      "name": "Empty"
    },
    {
      "x": -5,
      "y": 2,
      "z": 3,
      "name": "Empty"
    },
    {
      "x": -5,
      "y": 3,
      "z": 3,
      "name": "Empty"
    },
    {
      "x": -5,
      "y": 4,
      "z": 3,
      "name": "Empty"
    },
    {
      "x": -5,
      "y": -2,
      "z": 4,
      "name": "Soil_Dirt"
    },
    {
      "x": -5,
      "y": -1,
      "z": 4,
      "name": "Soil_Dirt"
    },
    {
      "x": -5,
      "y": 0,
      "z": 4,
      "name": "Soil_Grass"
    },
    {
      "x": -5,
      "y": 1,
      "z": 4,
      "name": "Empty"
    },
    {
      "x": -5,
      "y": 2,
      "z": 4,
      "name": "Empty"
    },
    {
      "x": -5,
      "y": 3,
      "z": 4,
      "name": "Empty"
    },
    {
      "x": -5,
      "y": 4,
      "z": 4,
      "name": "Empty"
    },
    {
      "x": -5,
      "y": -2,
      "z": 5,
      "name": "Soil_Dirt"
    },
    {
      "x": -5,
      "y": -1,
      "z": 5,
      "name": "Soil_Dirt"
    },
    {
      "x": -5,
      "y": 0,
      "z": 5,
      "name": "Soil_Grass"
    },
    {
      "x": -5,
      "y": 1,
      "z": 5,
      "name": "Empty"
    },
    {
      "x": -5,
      "y": 2,
      "z": 5,
      "name": "Empty"
    },
    {
      "x": -5,
      "y": 3,
      "z": 5,
      "name": "Empty"
    },
    {
      "x": -5,
      "y": 4,
      "z": 5,
      "name": "Empty"
    },
    {
      "x": -5,
      "y": -2,
      "z": 6,
      "name": "Soil_Dirt"
    },
    {
      "x": -5,
      "y": -1,
      "z": 6,
      "name": "Soil_Dirt"
    },
    {
      "x": -5,
      "y": 0,
      "z": 6,
      "name": "Soil_Grass"
    },
    {
      "x": -5,
      "y": 1,
      "z": 6,
      "name": "Empty"
    },
    {
      "x": -5,
      "y": 2,
      "z": 6,
      "name": "Empty"
    },
    {
      "x": -5,
      "y": 3,
      "z": 6,
      "name": "Empty"
    },
    {
      "x": -5,
      "y": 4,
      "z": 6,
      "name": "Empty"
    },
    {
      "x": -5,
      "y": -2,
      "z": 7,
      "name": "Soil_Dirt"
    },
    {
      "x": -5,
      "y": -1,
      "z": 7,
      "name": "Soil_Dirt"
    },
    {
      "x": -5,
      "y": 0,
      "z": 7,
      "name": "Soil_Grass"
    },
    {
      "x": -5,
      "y": 1,
      "z": 7,
      "name": "Empty"
    },
    {
      "x": -5,
      "y": 2,
      "z": 7,
      "name": "Empty"
    },
    {
      "x": -5,
      "y": 3,
      "z": 7,
      "name": "Empty"
    },
    {
      "x": -5,
      "y": 4,
      "z": 7,
      "name": "Empty"
    },
    {
      "x": -5,
      "y": -2,
      "z": 8,
      "name": "Soil_Dirt"
    },
    {
      "x": -5,
      "y": -1,
      "z": 8,
      "name": "Soil_Dirt"
    },
    {
      "x": -5,
      "y": 0,
      "z": 8,
      "name": "Soil_Grass"
    },
    {
      "x": -5,
      "y": 1,
      "z": 8,
      "name": "Empty"
    },
    {
      "x": -5,
      "y": 2,
      "z": 8,
      "name": "Empty"
    },
    {
      "x": -5,
      "y": 3,
      "z": 8,
      "name": "Empty"
    },
    {
      "x": -5,
      "y": 4,
      "z": 8,
      "name": "Empty"
    },
    {
      "x": -5,
      "y": -2,
      "z": 9,
      "name": "Soil_Dirt"
    },
    {
      "x": -5,
      "y": -1,
      "z": 9,
      "name": "Soil_Dirt"
    },
    {
      "x": -5,
      "y": 0,
      "z": 9,
      "name": "Soil_Grass"
    },
    {
      "x": -5,
      "y": 1,
      "z": 9,
      "name": "Empty"
    },
    {
      "x": -5,
      "y": 2,
      "z": 9,
      "name": "Empty"
    },
    {
      "x": -5,
      "y": 3,
      "z": 9,
      "name": "Empty"
    },
    {
      "x": -5,
      "y": 4,
      "z": 9,
      "name": "Empty"
    },
    {
      "x": -5,
      "y": -2,
      "z": 10,
      "name": "Soil_Dirt"
    },
    {
      "x": -5,
      "y": -1,
      "z": 10,
      "name": "Soil_Dirt"
    },
    {
      "x": -5,
      "y": 0,
      "z": 10,
      "name": "Soil_Grass"
    },
    {
      "x": -5,
      "y": 1,
      "z": 10,
      "name": "Empty"
    },
    {
      "x": -5,
      "y": 2,
      "z": 10,
      "name": "Empty"
    },
    {
      "x": -5,
      "y": 3,
      "z": 10,
      "name": "Empty"
    },
    {
      "x": -5,
      "y": 4,
      "z": 10,
      "name": "Empty"
    },
    {
      "x": -5,
      "y": -2,
      "z": 11,
      "name": "Soil_Dirt"
    },
    {
      "x": -5,
      "y": -1,
      "z": 11,
      "name": "Soil_Dirt"
    },
    {
      "x": -5,
      "y": 0,
      "z": 11,
      "name": "Soil_Grass"
    },
    {
      "x": -5,
      "y": 1,
      "z": 11,
      "name": "Empty"
    },
    {
      "x": -5,
      "y": 2,
      "z": 11,
      "name": "Empty"
    },
    {
      "x": -5,
      "y": 3,
      "z": 11,
      "name": "Empty"
    },
    {
      "x": -5,
      "y": 4,
      "z": 11,
      "name": "Empty"
    },
    {
      "x": -5,
      "y": -2,
      "z": 12,
      "name": "Soil_Dirt"
    },
    {
      "x": -5,
      "y": -1,
      "z": 12,
      "name": "Soil_Dirt"
    },
    {
      "x": -5,
      "y": 0,
      "z": 12,
      "name": "Soil_Grass"
    },
    {
      "x": -5,
      "y": 1,
      "z": 12,
      "name": "Empty"
    },
    {
      "x": -5,
      "y": 2,
      "z": 12,
      "name": "Empty"
    },
    {
      "x": -5,
      "y": 3,
      "z": 12,
      "name": "Empty"
    },
    {
      "x": -5,
      "y": 4,
      "z": 12,
      "name": "Empty"
    },
    {
      "x": -5,
      "y": -2,
      "z": 13,
      "name": "Soil_Dirt"
    },
    {
      "x": -5,
      "y": -1,
      "z": 13,
      "name": "Soil_Dirt"
    },
    {
      "x": -5,
      "y": 0,
      "z": 13,
      "name": "Soil_Grass"
    },
    {
      "x": -5,
      "y": 1,
      "z": 13,
      "name": "Empty"
    },
    {
      "x": -5,
      "y": 2,
      "z": 13,
      "name": "Empty"
    },
    {
      "x": -5,
      "y": 3,
      "z": 13,
      "name": "Empty"
    },
    {
      "x": -5,
      "y": 4,
      "z": 13,
      "name": "Empty"
    },
    {
      "x": -4,
      "y": -2,
      "z": -3,
      "name": "Soil_Dirt"
    },
    {
      "x": -4,
      "y": -1,
      "z": -3,
      "name": "Soil_Dirt"
    },
    {
      "x": -4,
      "y": 0,
      "z": -3,
      "name": "Soil_Grass"
    },
    {
      "x": -4,
      "y": 1,
      "z": -3,
      "name": "Empty"
    },
    {
      "x": -4,
      "y": 2,
      "z": -3,
      "name": "Empty"
    },
    {
      "x": -4,
      "y": 3,
      "z": -3,
      "name": "Empty"
    },
    {
      "x": -4,
      "y": 4,
      "z": -3,
      "name": "Empty"
    },
    {
      "x": -4,
      "y": -2,
      "z": -2,
      "name": "Soil_Dirt"
    },
    {
      "x": -4,
      "y": -1,
      "z": -2,
      "name": "Soil_Dirt"
    },
    {
      "x": -4,
      "y": 0,
      "z": -2,
      "name": "Soil_Grass"
    },
    {
      "x": -4,
      "y": 1,
      "z": -2,
      "name": "Empty"
    },
    {
      "x": -4,
      "y": 2,
      "z": -2,
      "name": "Empty"
    },
    {
      "x": -4,
      "y": 3,
      "z": -2,
      "name": "Empty"
    },
    {
      "x": -4,
      "y": 4,
      "z": -2,
      "name": "Empty"
    },
    {
      "x": -4,
      "y": -3,
      "z": -1,
      "name": "Rock_Stone"
    },
    {
      "x": -4,
      "y": -2,
      "z": -1,
      "name": "Soil_Dirt"
    },
    {
      "x": -4,
      "y": -1,
      "z": -1,
      "name": "Soil_Dirt"
    },
    {
      "x": -4,
      "y": 0,
      "z": -1,
      "name": "Soil_Grass"
    },
    {
      "x": -4,
      "y": 1,
      "z": -1,
      "name": "Empty"
    },
    {
      "x": -4,
      "y": 2,
      "z": -1,
      "name": "Empty"
    },
    {
      "x": -4,
      "y": 3,
      "z": -1,
      "name": "Empty"
    },
    {
      "x": -4,
      "y": 4,
      "z": -1,
      "name": "Empty"
    },
    {
      "x": -4,
      "y": -3,
      "z": 0,
      "name": "Rock_Stone"
    },
    {
      "x": -4,
      "y": -2,
      "z": 0,
      "name": "Soil_Dirt"
    },
    {
      "x": -4,
      "y": -1,
      "z": 0,
      "name": "Soil_Dirt"
    },
    {
      "x": -4,
      "y": 0,
      "z": 0,
      "name": "Soil_Grass"
    },
    {
      "x": -4,
      "y": 1,
      "z": 0,
      "name": "Empty"
    },
    {
      "x": -4,
      "y": 2,
      "z": 0,
      "name": "Empty"
    },
    {
      "x": -4,
      "y": 3,
      "z": 0,
      "name": "Empty"
    },
    {
      "x": -4,
      "y": 4,
      "z": 0,
      "name": "Empty"
    },
    {
      "x": -4,
      "y": -3,
      "z": 1,
      "name": "Rock_Stone"
    },
    {
      "x": -4,
      "y": -2,
      "z": 1,
      "name": "Soil_Dirt"
    },
    {
      "x": -4,
      "y": -1,
      "z": 1,
      "name": "Soil_Dirt"
    },
    {
      "x": -4,
      "y": 0,
      "z": 1,
      "name": "Soil_Grass"
    },
    {
      "x": -4,
      "y": 1,
      "z": 1,
      "name": "Empty"
    },
    {
      "x": -4,
      "y": 2,
      "z": 1,
      "name": "Empty"
    },
    {
      "x": -4,
      "y": 3,
      "z": 1,
      "name": "Empty"
    },
    {
      "x": -4,
      "y": 4,
      "z": 1,
      "name": "Empty"
    },
    {
      "x": -4,
      "y": -3,
      "z": 2,
      "name": "Rock_Stone"
    },
    {
      "x": -4,
      "y": -2,
      "z": 2,
      "name": "Soil_Dirt"
    },
    {
      "x": -4,
      "y": -1,
      "z": 2,
      "name": "Soil_Dirt"
    },
    {
      "x": -4,
      "y": 0,
      "z": 2,
      "name": "Soil_Grass"
    },
    {
      "x": -4,
      "y": 1,
      "z": 2,
      "name": "Empty"
    },
    {
      "x": -4,
      "y": 2,
      "z": 2,
      "name": "Empty"
    },
    {
      "x": -4,
      "y": 3,
      "z": 2,
      "name": "Empty"
    },
    {
      "x": -4,
      "y": 4,
      "z": 2,
      "name": "Empty"
    },
    {
      "x": -4,
      "y": -3,
      "z": 3,
      "name": "Rock_Stone"
    },
    {
      "x": -4,
      "y": -2,
      "z": 3,
      "name": "Soil_Dirt"
    },
    {
      "x": -4,
      "y": -1,
      "z": 3,
      "name": "Soil_Dirt"
    },
    {
      "x": -4,
      "y": 0,
      "z": 3,
      "name": "Soil_Grass"
    },
    {
      "x": -4,
      "y": 1,
      "z": 3,
      "name": "Empty"
    },
    {
      "x": -4,
      "y": 2,
      "z": 3,
      "name": "Empty"
    },
    {
      "x": -4,
      "y": 3,
      "z": 3,
      "name": "Empty"
    },
    {
      "x": -4,
      "y": 4,
      "z": 3,
      "name": "Empty"
    },
    {
      "x": -4,
      "y": -3,
      "z": 4,
      "name": "Rock_Stone"
    },
    {
      "x": -4,
      "y": -2,
      "z": 4,
      "name": "Soil_Dirt"
    },
    {
      "x": -4,
      "y": -1,
      "z": 4,
      "name": "Soil_Dirt"
    },
    {
      "x": -4,
      "y": 0,
      "z": 4,
      "name": "Soil_Grass"
    },
    {
      "x": -4,
      "y": 1,
      "z": 4,
      "name": "Empty"
    },
    {
      "x": -4,
      "y": 2,
      "z": 4,
      "name": "Empty"
    },
    {
      "x": -4,
      "y": 3,
      "z": 4,
      "name": "Empty"
    },
    {
      "x": -4,
      "y": 4,
      "z": 4,
      "name": "Empty"
    },
    {
      "x": -4,
      "y": -3,
      "z": 5,
      "name": "Rock_Stone"
    },
    {
      "x": -4,
      "y": -2,
      "z": 5,
      "name": "Soil_Dirt"
    },
    {
      "x": -4,
      "y": -1,
      "z": 5,
      "name": "Soil_Dirt"
    },
    {
      "x": -4,
      "y": 0,
      "z": 5,
      "name": "Soil_Grass"
    },
    {
      "x": -4,
      "y": 1,
      "z": 5,
      "name": "Empty"
    },
    {
      "x": -4,
      "y": 2,
      "z": 5,
      "name": "Empty"
    },
    {
      "x": -4,
      "y": 3,
      "z": 5,
      "name": "Empty"
    },
    {
      "x": -4,
      "y": 4,
      "z": 5,
      "name": "Empty"
    },
    {
      "x": -4,
      "y": -3,
      "z": 6,
      "name": "Rock_Stone"
    },
    {
      "x": -4,
      "y": -2,
      "z": 6,
      "name": "Soil_Dirt"
    },
    {
      "x": -4,
      "y": -1,
      "z": 6,
      "name": "Soil_Dirt"
    },
    {
      "x": -4,
      "y": 0,
      "z": 6,
      "name": "Soil_Grass"
    },
    {
      "x": -4,
      "y": 1,
      "z": 6,
      "name": "Plant_Grass_Sharp"
    },
    {
      "x": -4,
      "y": 2,
      "z": 6,
      "name": "Empty"
    },
    {
      "x": -4,
      "y": 3,
      "z": 6,
      "name": "Empty"
    },
    {
      "x": -4,
      "y": 4,
      "z": 6,
      "name": "Empty"
    },
    {
      "x": -4,
      "y": -3,
      "z": 7,
      "name": "Rock_Stone"
    },
    {
      "x": -4,
      "y": -2,
      "z": 7,
      "name": "Soil_Dirt"
    },
    {
      "x": -4,
      "y": -1,
      "z": 7,
      "name": "Soil_Dirt"
    },
    {
      "x": -4,
      "y": 0,
      "z": 7,
      "name": "Soil_Grass"
    },
    {
      "x": -4,
      "y": 1,
      "z": 7,
      "name": "Empty"
    },
    {
      "x": -4,
      "y": 2,
      "z": 7,
      "name": "Empty"
    },
    {
      "x": -4,
      "y": 3,
      "z": 7,
      "name": "Empty"
    },
    {
      "x": -4,
      "y": 4,
      "z": 7,
      "name": "Empty"
    },
    {
      "x": -4,
      "y": -3,
      "z": 8,
      "name": "Rock_Stone"
    },
    {
      "x": -4,
      "y": -2,
      "z": 8,
      "name": "Soil_Dirt"
    },
    {
      "x": -4,
      "y": -1,
      "z": 8,
      "name": "Soil_Dirt"
    },
    {
      "x": -4,
      "y": 0,
      "z": 8,
      "name": "Soil_Grass"
    },
    {
      "x": -4,
      "y": 1,
      "z": 8,
      "name": "Empty"
    },
    {
      "x": -4,
      "y": 2,
      "z": 8,
      "name": "Empty"
    },
    {
      "x": -4,
      "y": 3,
      "z": 8,
      "name": "Empty"
    },
    {
      "x": -4,
      "y": 4,
      "z": 8,
      "name": "Empty"
    },
    {
      "x": -4,
      "y": -3,
      "z": 9,
      "name": "Rock_Stone"
    },
    {
      "x": -4,
      "y": -2,
      "z": 9,
      "name": "Soil_Dirt"
    },
    {
      "x": -4,
      "y": -1,
      "z": 9,
      "name": "Soil_Dirt"
    },
    {
      "x": -4,
      "y": 0,
      "z": 9,
      "name": "Soil_Grass"
    },
    {
      "x": -4,
      "y": 1,
      "z": 9,
      "name": "Empty"
    },
    {
      "x": -4,
      "y": 2,
      "z": 9,
      "name": "Empty"
    },
    {
      "x": -4,
      "y": 3,
      "z": 9,
      "name": "Empty"
    },
    {
      "x": -4,
      "y": 4,
      "z": 9,
      "name": "Empty"
    },
    {
      "x": -4,
      "y": -3,
      "z": 10,
      "name": "Rock_Stone"
    },
    {
      "x": -4,
      "y": -2,
      "z": 10,
      "name": "Soil_Dirt"
    },
    {
      "x": -4,
      "y": -1,
      "z": 10,
      "name": "Soil_Dirt"
    },
    {
      "x": -4,
      "y": 0,
      "z": 10,
      "name": "Soil_Grass"
    },
    {
      "x": -4,
      "y": 1,
      "z": 10,
      "name": "Empty"
    },
    {
      "x": -4,
      "y": 2,
      "z": 10,
      "name": "Empty"
    },
    {
      "x": -4,
      "y": 3,
      "z": 10,
      "name": "Empty"
    },
    {
      "x": -4,
      "y": 4,
      "z": 10,
      "name": "Empty"
    },
    {
      "x": -4,
      "y": -3,
      "z": 11,
      "name": "Rock_Stone"
    },
    {
      "x": -4,
      "y": -2,
      "z": 11,
      "name": "Soil_Dirt"
    },
    {
      "x": -4,
      "y": -1,
      "z": 11,
      "name": "Soil_Dirt"
    },
    {
      "x": -4,
      "y": 0,
      "z": 11,
      "name": "Soil_Grass"
    },
    {
      "x": -4,
      "y": 1,
      "z": 11,
      "name": "Plant_Grass_Sharp"
    },
    {
      "x": -4,
      "y": 2,
      "z": 11,
      "name": "Empty"
    },
    {
      "x": -4,
      "y": 3,
      "z": 11,
      "name": "Empty"
    },
    {
      "x": -4,
      "y": 4,
      "z": 11,
      "name": "Empty"
    },
    {
      "x": -4,
      "y": -3,
      "z": 12,
      "name": "Rock_Stone"
    },
    {
      "x": -4,
      "y": -2,
      "z": 12,
      "name": "Soil_Dirt"
    },
    {
      "x": -4,
      "y": -1,
      "z": 12,
      "name": "Soil_Dirt"
    },
    {
      "x": -4,
      "y": 0,
      "z": 12,
      "name": "Soil_Grass"
    },
    {
      "x": -4,
      "y": 1,
      "z": 12,
      "name": "Empty"
    },
    {
      "x": -4,
      "y": 2,
      "z": 12,
      "name": "Empty"
    },
    {
      "x": -4,
      "y": 3,
      "z": 12,
      "name": "Empty"
    },
    {
      "x": -4,
      "y": 4,
      "z": 12,
      "name": "Empty"
    },
    {
      "x": -4,
      "y": -2,
      "z": 13,
      "name": "Soil_Dirt"
    },
    {
      "x": -4,
      "y": -1,
      "z": 13,
      "name": "Soil_Dirt"
    },
    {
      "x": -4,
      "y": 0,
      "z": 13,
      "name": "Soil_Grass"
    },
    {
      "x": -4,
      "y": 1,
      "z": 13,
      "name": "Empty"
    },
    {
      "x": -4,
      "y": 2,
      "z": 13,
      "name": "Empty"
    },
    {
      "x": -4,
      "y": 3,
      "z": 13,
      "name": "Empty"
    },
    {
      "x": -4,
      "y": 4,
      "z": 13,
      "name": "Empty"
    },
    {
      "x": -4,
      "y": -2,
      "z": 14,
      "name": "Soil_Dirt"
    },
    {
      "x": -4,
      "y": -1,
      "z": 14,
      "name": "Soil_Dirt"
    },
    {
      "x": -4,
      "y": 0,
      "z": 14,
      "name": "Soil_Grass"
    },
    {
      "x": -4,
      "y": 1,
      "z": 14,
      "name": "Empty"
    },
    {
      "x": -4,
      "y": 2,
      "z": 14,
      "name": "Empty"
    },
    {
      "x": -4,
      "y": 3,
      "z": 14,
      "name": "Empty"
    },
    {
      "x": -4,
      "y": 4,
      "z": 14,
      "name": "Empty"
    },
    {
      "x": -3,
      "y": -2,
      "z": -4,
      "name": "Soil_Dirt"
    },
    {
      "x": -3,
      "y": -1,
      "z": -4,
      "name": "Soil_Dirt"
    },
    {
      "x": -3,
      "y": 0,
      "z": -4,
      "name": "Soil_Grass"
    },
    {
      "x": -3,
      "y": 1,
      "z": -4,
      "name": "Empty"
    },
    {
      "x": -3,
      "y": 2,
      "z": -4,
      "name": "Empty"
    },
    {
      "x": -3,
      "y": 3,
      "z": -4,
      "name": "Empty"
    },
    {
      "x": -3,
      "y": 4,
      "z": -4,
      "name": "Empty"
    },
    {
      "x": -3,
      "y": -2,
      "z": -3,
      "name": "Soil_Dirt"
    },
    {
      "x": -3,
      "y": -1,
      "z": -3,
      "name": "Soil_Dirt"
    },
    {
      "x": -3,
      "y": 0,
      "z": -3,
      "name": "Soil_Grass"
    },
    {
      "x": -3,
      "y": 1,
      "z": -3,
      "name": "Empty"
    },
    {
      "x": -3,
      "y": 2,
      "z": -3,
      "name": "Empty"
    },
    {
      "x": -3,
      "y": 3,
      "z": -3,
      "name": "Empty"
    },
    {
      "x": -3,
      "y": 4,
      "z": -3,
      "name": "Empty"
    },
    {
      "x": -3,
      "y": -3,
      "z": -2,
      "name": "Rock_Stone"
    },
    {
      "x": -3,
      "y": -2,
      "z": -2,
      "name": "Soil_Dirt"
    },
    {
      "x": -3,
      "y": -1,
      "z": -2,
      "name": "Soil_Dirt"
    },
    {
      "x": -3,
      "y": 0,
      "z": -2,
      "name": "Soil_Grass"
    },
    {
      "x": -3,
      "y": 1,
      "z": -2,
      "name": "Empty"
    },
    {
      "x": -3,
      "y": 2,
      "z": -2,
      "name": "Empty"
    },
    {
      "x": -3,
      "y": 3,
      "z": -2,
      "name": "Empty"
    },
    {
      "x": -3,
      "y": 4,
      "z": -2,
      "name": "Empty"
    },
    {
      "x": -3,
      "y": -3,
      "z": -1,
      "name": "Rock_Stone"
    },
    {
      "x": -3,
      "y": -2,
      "z": -1,
      "name": "Soil_Dirt"
    },
    {
      "x": -3,
      "y": -1,
      "z": -1,
      "name": "Soil_Dirt"
    },
    {
      "x": -3,
      "y": 0,
      "z": -1,
      "name": "Soil_Grass"
    },
    {
      "x": -3,
      "y": 1,
      "z": -1,
      "name": "Empty"
    },
    {
      "x": -3,
      "y": 2,
      "z": -1,
      "name": "Empty"
    },
    {
      "x": -3,
      "y": 3,
      "z": -1,
      "name": "Empty"
    },
    {
      "x": -3,
      "y": 4,
      "z": -1,
      "name": "Empty"
    },
    {
      "x": -3,
      "y": -4,
      "z": 0,
      "name": "Rock_Stone"
    },
    {
      "x": -3,
      "y": -3,
      "z": 0,
      "name": "Rock_Stone"
    },
    {
      "x": -3,
      "y": -2,
      "z": 0,
      "name": "Soil_Dirt"
    },
    {
      "x": -3,
      "y": -1,
      "z": 0,
      "name": "Soil_Dirt"
    },
    {
      "x": -3,
      "y": 0,
      "z": 0,
      "name": "Soil_Grass"
    },
    {
      "x": -3,
      "y": 1,
      "z": 0,
      "name": "Plant_Bush_Green"
    },
    {
      "x": -3,
      "y": 2,
      "z": 0,
      "name": "Empty"
    },
    {
      "x": -3,
      "y": 3,
      "z": 0,
      "name": "Empty"
    },
    {
      "x": -3,
      "y": 4,
      "z": 0,
      "name": "Empty"
    },
    {
      "x": -3,
      "y": -4,
      "z": 1,
      "name": "Rock_Stone"
    },
    {
      "x": -3,
      "y": -3,
      "z": 1,
      "name": "Rock_Stone"
    },
    {
      "x": -3,
      "y": -2,
      "z": 1,
      "name": "Soil_Dirt"
    },
    {
      "x": -3,
      "y": -1,
      "z": 1,
      "name": "Soil_Dirt"
    },
    {
      "x": -3,
      "y": 0,
      "z": 1,
      "name": "Soil_Grass"
    },
    {
      "x": -3,
      "y": 1,
      "z": 1,
      "name": "Empty"
    },
    {
      "x": -3,
      "y": 2,
      "z": 1,
      "name": "Empty"
    },
    {
      "x": -3,
      "y": 3,
      "z": 1,
      "name": "Empty"
    },
    {
      "x": -3,
      "y": 4,
      "z": 1,
      "name": "Empty"
    },
    {
      "x": -3,
      "y": -4,
      "z": 2,
      "name": "Rock_Stone"
    },
    {
      "x": -3,
      "y": -3,
      "z": 2,
      "name": "Rock_Stone"
    },
    {
      "x": -3,
      "y": -2,
      "z": 2,
      "name": "Soil_Dirt"
    },
    {
      "x": -3,
      "y": -1,
      "z": 2,
      "name": "Soil_Dirt"
    },
    {
      "x": -3,
      "y": 0,
      "z": 2,
      "name": "Soil_Grass"
    },
    {
      "x": -3,
      "y": 1,
      "z": 2,
      "name": "Empty"
    },
    {
      "x": -3,
      "y": 2,
      "z": 2,
      "name": "Empty"
    },
    {
      "x": -3,
      "y": 3,
      "z": 2,
      "name": "Empty"
    },
    {
      "x": -3,
      "y": 4,
      "z": 2,
      "name": "Empty"
    },
    {
      "x": -3,
      "y": -4,
      "z": 3,
      "name": "Rock_Stone"
    },
    {
      "x": -3,
      "y": -3,
      "z": 3,
      "name": "Rock_Stone"
    },
    {
      "x": -3,
      "y": -2,
      "z": 3,
      "name": "Soil_Dirt"
    },
    {
      "x": -3,
      "y": -1,
      "z": 3,
      "name": "Soil_Dirt"
    },
    {
      "x": -3,
      "y": 0,
      "z": 3,
      "name": "Soil_Grass"
    },
    {
      "x": -3,
      "y": 1,
      "z": 3,
      "name": "Plant_Flower_Common_Pink"
    },
    {
      "x": -3,
      "y": 2,
      "z": 3,
      "name": "Empty"
    },
    {
      "x": -3,
      "y": 3,
      "z": 3,
      "name": "Empty"
    },
    {
      "x": -3,
      "y": 4,
      "z": 3,
      "name": "Empty"
    },
    {
      "x": -3,
      "y": -4,
      "z": 4,
      "name": "Rock_Stone"
    },
    {
      "x": -3,
      "y": -3,
      "z": 4,
      "name": "Rock_Stone"
    },
    {
      "x": -3,
      "y": -2,
      "z": 4,
      "name": "Soil_Dirt"
    },
    {
      "x": -3,
      "y": -1,
      "z": 4,
      "name": "Soil_Dirt"
    },
    {
      "x": -3,
      "y": 0,
      "z": 4,
      "name": "Soil_Grass"
    },
    {
      "x": -3,
      "y": 1,
      "z": 4,
      "name": "Empty"
    },
    {
      "x": -3,
      "y": 2,
      "z": 4,
      "name": "Empty"
    },
    {
      "x": -3,
      "y": 3,
      "z": 4,
      "name": "Empty"
    },
    {
      "x": -3,
      "y": 4,
      "z": 4,
      "name": "Empty"
    },
    {
      "x": -3,
      "y": -4,
      "z": 5,
      "name": "Rock_Stone"
    },
    {
      "x": -3,
      "y": -3,
      "z": 5,
      "name": "Rock_Stone"
    },
    {
      "x": -3,
      "y": -2,
      "z": 5,
      "name": "Soil_Dirt"
    },
    {
      "x": -3,
      "y": -1,
      "z": 5,
      "name": "Soil_Dirt"
    },
    {
      "x": -3,
      "y": 0,
      "z": 5,
      "name": "Soil_Grass"
    },
    {
      "x": -3,
      "y": 1,
      "z": 5,
      "name": "Empty"
    },
    {
      "x": -3,
      "y": 2,
      "z": 5,
      "name": "Empty"
    },
    {
      "x": -3,
      "y": 3,
      "z": 5,
      "name": "Empty"
    },
    {
      "x": -3,
      "y": 4,
      "z": 5,
      "name": "Empty"
    },
    {
      "x": -3,
      "y": -4,
      "z": 6,
      "name": "Rock_Stone"
    },
    {
      "x": -3,
      "y": -3,
      "z": 6,
      "name": "Rock_Stone"
    },
    {
      "x": -3,
      "y": -2,
      "z": 6,
      "name": "Soil_Dirt"
    },
    {
      "x": -3,
      "y": -1,
      "z": 6,
      "name": "Soil_Dirt"
    },
    {
      "x": -3,
      "y": 0,
      "z": 6,
      "name": "Soil_Grass"
    },
    {
      "x": -3,
      "y": 1,
      "z": 6,
      "name": "Wood_Softwood_Fence",
      "rotation": 1
    },
    {
      "x": -3,
      "y": 2,
      "z": 6,
      "name": "Empty"
    },
    {
      "x": -3,
      "y": 3,
      "z": 6,
      "name": "Empty"
    },
    {
      "x": -3,
      "y": 4,
      "z": 6,
      "name": "Empty"
    },
    {
      "x": -3,
      "y": -4,
      "z": 7,
      "name": "Rock_Stone"
    },
    {
      "x": -3,
      "y": -3,
      "z": 7,
      "name": "Rock_Stone"
    },
    {
      "x": -3,
      "y": -2,
      "z": 7,
      "name": "Soil_Dirt"
    },
    {
      "x": -3,
      "y": -1,
      "z": 7,
      "name": "Soil_Dirt"
    },
    {
      "x": -3,
      "y": 0,
      "z": 7,
      "name": "Soil_Grass"
    },
    {
      "x": -3,
      "y": 1,
      "z": 7,
      "name": "Wood_Softwood_Fence",
      "rotation": 1
    },
    {
      "x": -3,
      "y": 2,
      "z": 7,
      "name": "Empty"
    },
    {
      "x": -3,
      "y": 3,
      "z": 7,
      "name": "Empty"
    },
    {
      "x": -3,
      "y": 4,
      "z": 7,
      "name": "Empty"
    },
    {
      "x": -3,
      "y": -4,
      "z": 8,
      "name": "Rock_Stone"
    },
    {
      "x": -3,
      "y": -3,
      "z": 8,
      "name": "Rock_Stone"
    },
    {
      "x": -3,
      "y": -2,
      "z": 8,
      "name": "Soil_Dirt"
    },
    {
      "x": -3,
      "y": -1,
      "z": 8,
      "name": "Soil_Dirt"
    },
    {
      "x": -3,
      "y": 0,
      "z": 8,
      "name": "Soil_Grass"
    },
    {
      "x": -3,
      "y": 1,
      "z": 8,
      "name": "Wood_Softwood_Fence",
      "rotation": 1
    },
    {
      "x": -3,
      "y": 2,
      "z": 8,
      "name": "Empty"
    },
    {
      "x": -3,
      "y": 3,
      "z": 8,
      "name": "Empty"
    },
    {
      "x": -3,
      "y": 4,
      "z": 8,
      "name": "Empty"
    },
    {
      "x": -3,
      "y": -4,
      "z": 9,
      "name": "Rock_Stone"
    },
    {
      "x": -3,
      "y": -3,
      "z": 9,
      "name": "Rock_Stone"
    },
    {
      "x": -3,
      "y": -2,
      "z": 9,
      "name": "Soil_Dirt"
    },
    {
      "x": -3,
      "y": -1,
      "z": 9,
      "name": "Soil_Dirt"
    },
    {
      "x": -3,
      "y": 0,
      "z": 9,
      "name": "Soil_Grass"
    },
    {
      "x": -3,
      "y": 1,
      "z": 9,
      "name": "Wood_Softwood_Fence",
      "rotation": 1
    },
    {
      "x": -3,
      "y": 2,
      "z": 9,
      "name": "Empty"
    },
    {
      "x": -3,
      "y": 3,
      "z": 9,
      "name": "Empty"
    },
    {
      "x": -3,
      "y": 4,
      "z": 9,
      "name": "Empty"
    },
    {
      "x": -3,
      "y": -4,
      "z": 10,
      "name": "Rock_Stone"
    },
    {
      "x": -3,
      "y": -3,
      "z": 10,
      "name": "Rock_Stone"
    },
    {
      "x": -3,
      "y": -2,
      "z": 10,
      "name": "Soil_Dirt"
    },
    {
      "x": -3,
      "y": -1,
      "z": 10,
      "name": "Soil_Dirt"
    },
    {
      "x": -3,
      "y": 0,
      "z": 10,
      "name": "Soil_Grass"
    },
    {
      "x": -3,
      "y": 1,
      "z": 10,
      "name": "Wood_Softwood_Fence",
      "rotation": 1
    },
    {
      "x": -3,
      "y": 2,
      "z": 10,
      "name": "Empty"
    },
    {
      "x": -3,
      "y": 3,
      "z": 10,
      "name": "Empty"
    },
    {
      "x": -3,
      "y": 4,
      "z": 10,
      "name": "Empty"
    },
    {
      "x": -3,
      "y": -4,
      "z": 11,
      "name": "Rock_Stone"
    },
    {
      "x": -3,
      "y": -3,
      "z": 11,
      "name": "Rock_Stone"
    },
    {
      "x": -3,
      "y": -2,
      "z": 11,
      "name": "Soil_Dirt"
    },
    {
      "x": -3,
      "y": -1,
      "z": 11,
      "name": "Soil_Dirt"
    },
    {
      "x": -3,
      "y": 0,
      "z": 11,
      "name": "Soil_Grass"
    },
    {
      "x": -3,
      "y": 1,
      "z": 11,
      "name": "Wood_Softwood_Fence",
      "rotation": 1
    },
    {
      "x": -3,
      "y": 2,
      "z": 11,
      "name": "Empty"
    },
    {
      "x": -3,
      "y": 3,
      "z": 11,
      "name": "Empty"
    },
    {
      "x": -3,
      "y": 4,
      "z": 11,
      "name": "Empty"
    },
    {
      "x": -3,
      "y": -3,
      "z": 12,
      "name": "Rock_Stone"
    },
    {
      "x": -3,
      "y": -2,
      "z": 12,
      "name": "Soil_Dirt"
    },
    {
      "x": -3,
      "y": -1,
      "z": 12,
      "name": "Soil_Dirt"
    },
    {
      "x": -3,
      "y": 0,
      "z": 12,
      "name": "Soil_Grass"
    },
    {
      "x": -3,
      "y": 1,
      "z": 12,
      "name": "Wood_Softwood_Fence",
      "rotation": 1
    },
    {
      "x": -3,
      "y": 2,
      "z": 12,
      "name": "Empty"
    },
    {
      "x": -3,
      "y": 3,
      "z": 12,
      "name": "Empty"
    },
    {
      "x": -3,
      "y": 4,
      "z": 12,
      "name": "Empty"
    },
    {
      "x": -3,
      "y": -3,
      "z": 13,
      "name": "Rock_Stone"
    },
    {
      "x": -3,
      "y": -2,
      "z": 13,
      "name": "Soil_Dirt"
    },
    {
      "x": -3,
      "y": -1,
      "z": 13,
      "name": "Soil_Dirt"
    },
    {
      "x": -3,
      "y": 0,
      "z": 13,
      "name": "Soil_Grass"
    },
    {
      "x": -3,
      "y": 1,
      "z": 13,
      "name": "Wood_Softwood_Fence",
      "rotation": 1
    },
    {
      "x": -3,
      "y": 2,
      "z": 13,
      "name": "Empty"
    },
    {
      "x": -3,
      "y": 3,
      "z": 13,
      "name": "Empty"
    },
    {
      "x": -3,
      "y": 4,
      "z": 13,
      "name": "Empty"
    },
    {
      "x": -3,
      "y": -2,
      "z": 14,
      "name": "Soil_Dirt"
    },
    {
      "x": -3,
      "y": -1,
      "z": 14,
      "name": "Soil_Dirt"
    },
    {
      "x": -3,
      "y": 0,
      "z": 14,
      "name": "Soil_Grass"
    },
    {
      "x": -3,
      "y": 1,
      "z": 14,
      "name": "*Wood_Softwood_Fence_State_Definitions_Corner",
      "rotation": 2
    },
    {
      "x": -3,
      "y": 2,
      "z": 14,
      "name": "Empty"
    },
    {
      "x": -3,
      "y": 3,
      "z": 14,
      "name": "Empty"
    },
    {
      "x": -3,
      "y": 4,
      "z": 14,
      "name": "Empty"
    },
    {
      "x": -3,
      "y": -2,
      "z": 15,
      "name": "Soil_Dirt"
    },
    {
      "x": -3,
      "y": -1,
      "z": 15,
      "name": "Soil_Dirt"
    },
    {
      "x": -3,
      "y": 0,
      "z": 15,
      "name": "Soil_Grass"
    },
    {
      "x": -3,
      "y": 1,
      "z": 15,
      "name": "Empty"
    },
    {
      "x": -3,
      "y": 2,
      "z": 15,
      "name": "Empty"
    },
    {
      "x": -3,
      "y": 3,
      "z": 15,
      "name": "Empty"
    },
    {
      "x": -3,
      "y": 4,
      "z": 15,
      "name": "Empty"
    },
    {
      "x": -2,
      "y": -2,
      "z": -4,
      "name": "Soil_Dirt"
    },
    {
      "x": -2,
      "y": -1,
      "z": -4,
      "name": "Soil_Dirt"
    },
    {
      "x": -2,
      "y": 0,
      "z": -4,
      "name": "Soil_Grass"
    },
    {
      "x": -2,
      "y": 1,
      "z": -4,
      "name": "Empty"
    },
    {
      "x": -2,
      "y": 2,
      "z": -4,
      "name": "Empty"
    },
    {
      "x": -2,
      "y": 3,
      "z": -4,
      "name": "Empty"
    },
    {
      "x": -2,
      "y": 4,
      "z": -4,
      "name": "Empty"
    },
    {
      "x": -2,
      "y": -3,
      "z": -3,
      "name": "Rock_Stone"
    },
    {
      "x": -2,
      "y": -2,
      "z": -3,
      "name": "Soil_Dirt"
    },
    {
      "x": -2,
      "y": -1,
      "z": -3,
      "name": "Soil_Dirt"
    },
    {
      "x": -2,
      "y": 0,
      "z": -3,
      "name": "Soil_Grass"
    },
    {
      "x": -2,
      "y": 1,
      "z": -3,
      "name": "Plant_Grass_Sharp"
    },
    {
      "x": -2,
      "y": 2,
      "z": -3,
      "name": "Empty"
    },
    {
      "x": -2,
      "y": 3,
      "z": -3,
      "name": "Empty"
    },
    {
      "x": -2,
      "y": 4,
      "z": -3,
      "name": "Empty"
    },
    {
      "x": -2,
      "y": -3,
      "z": -2,
      "name": "Rock_Stone"
    },
    {
      "x": -2,
      "y": -2,
      "z": -2,
      "name": "Soil_Dirt"
    },
    {
      "x": -2,
      "y": -1,
      "z": -2,
      "name": "Soil_Dirt"
    },
    {
      "x": -2,
      "y": 0,
      "z": -2,
      "name": "Soil_Grass"
    },
    {
      "x": -2,
      "y": 1,
      "z": -2,
      "name": "Empty"
    },
    {
      "x": -2,
      "y": 2,
      "z": -2,
      "name": "Empty"
    },
    {
      "x": -2,
      "y": 3,
      "z": -2,
      "name": "Empty"
    },
    {
      "x": -2,
      "y": 4,
      "z": -2,
      "name": "Wood_Softwood_Roof",
      "rotation": 2
    },
    {
      "x": -2,
      "y": -4,
      "z": -1,
      "name": "Rock_Stone"
    },
    {
      "x": -2,
      "y": -3,
      "z": -1,
      "name": "Rock_Stone"
    },
    {
      "x": -2,
      "y": -2,
      "z": -1,
      "name": "Soil_Dirt"
    },
    {
      "x": -2,
      "y": -1,
      "z": -1,
      "name": "Soil_Dirt"
    },
    {
      "x": -2,
      "y": 0,
      "z": -1,
      "name": "Soil_Grass"
    },
    {
      "x": -2,
      "y": 1,
      "z": -1,
      "name": "Empty"
    },
    {
      "x": -2,
      "y": 2,
      "z": -1,
      "name": "Empty"
    },
    {
      "x": -2,
      "y": 3,
      "z": -1,
      "name": "Empty"
    },
    {
      "x": -2,
      "y": 4,
      "z": -1,
      "name": "Empty"
    },
    {
      "x": -2,
      "y": 5,
      "z": -1,
      "name": "Wood_Softwood_Roof",
      "rotation": 2
    },
    {
      "x": -2,
      "y": -4,
      "z": 0,
      "name": "Rock_Stone"
    },
    {
      "x": -2,
      "y": -3,
      "z": 0,
      "name": "Rock_Stone"
    },
    {
      "x": -2,
      "y": -2,
      "z": 0,
      "name": "Soil_Dirt"
    },
    {
      "x": -2,
      "y": -1,
      "z": 0,
      "name": "Soil_Dirt"
    },
    {
      "x": -2,
      "y": 0,
      "z": 0,
      "name": "Soil_Grass"
    },
    {
      "x": -2,
      "y": 1,
      "z": 0,
      "name": "Empty"
    },
    {
      "x": -2,
      "y": 2,
      "z": 0,
      "name": "Empty"
    },
    {
      "x": -2,
      "y": 3,
      "z": 0,
      "name": "Empty"
    },
    {
      "x": -2,
      "y": 4,
      "z": 0,
      "name": "Empty"
    },
    {
      "x": -2,
      "y": 5,
      "z": 0,
      "name": "Empty"
    },
    {
      "x": -2,
      "y": 6,
      "z": 0,
      "name": "Wood_Softwood_Roof",
      "rotation": 2
    },
    {
      "x": -2,
      "y": -4,
      "z": 1,
      "name": "Rock_Stone"
    },
    {
      "x": -2,
      "y": -3,
      "z": 1,
      "name": "Rock_Stone"
    },
    {
      "x": -2,
      "y": -2,
      "z": 1,
      "name": "Soil_Dirt"
    },
    {
      "x": -2,
      "y": -1,
      "z": 1,
      "name": "Soil_Dirt"
    },
    {
      "x": -2,
      "y": 0,
      "z": 1,
      "name": "Soil_Grass"
    },
    {
      "x": -2,
      "y": 1,
      "z": 1,
      "name": "Empty"
    },
    {
      "x": -2,
      "y": 2,
      "z": 1,
      "name": "Empty"
    },
    {
      "x": -2,
      "y": 3,
      "z": 1,
      "name": "Empty"
    },
    {
      "x": -2,
      "y": 4,
      "z": 1,
      "name": "Empty"
    },
    {
      "x": -2,
      "y": 5,
      "z": 1,
      "name": "Empty"
    },
    {
      "x": -2,
      "y": 6,
      "z": 1,
      "name": "Empty"
    },
    {
      "x": -2,
      "y": 7,
      "z": 1,
      "name": "Wood_Softwood_Roof",
      "rotation": 2
    },
    {
      "x": -2,
      "y": -4,
      "z": 2,
      "name": "Rock_Stone"
    },
    {
      "x": -2,
      "y": -3,
      "z": 2,
      "name": "Rock_Stone"
    },
    {
      "x": -2,
      "y": -2,
      "z": 2,
      "name": "Soil_Dirt"
    },
    {
      "x": -2,
      "y": -1,
      "z": 2,
      "name": "Soil_Dirt"
    },
    {
      "x": -2,
      "y": 0,
      "z": 2,
      "name": "Soil_Grass"
    },
    {
      "x": -2,
      "y": 1,
      "z": 2,
      "name": "Empty"
    },
    {
      "x": -2,
      "y": 2,
      "z": 2,
      "name": "Empty"
    },
    {
      "x": -2,
      "y": 3,
      "z": 2,
      "name": "Empty"
    },
    {
      "x": -2,
      "y": 4,
      "z": 2,
      "name": "Empty"
    },
    {
      "x": -2,
      "y": 5,
      "z": 2,
      "name": "Empty"
    },
    {
      "x": -2,
      "y": 6,
      "z": 2,
      "name": "Empty"
    },
    {
      "x": -2,
      "y": 7,
      "z": 2,
      "name": "Empty"
    },
    {
      "x": -2,
      "y": 8,
      "z": 2,
      "name": "*Wood_Softwood_Roof_State_Definitions_Topper"
    },
    {
      "x": -2,
      "y": -4,
      "z": 3,
      "name": "Rock_Stone"
    },
    {
      "x": -2,
      "y": -3,
      "z": 3,
      "name": "Rock_Stone"
    },
    {
      "x": -2,
      "y": -2,
      "z": 3,
      "name": "Soil_Dirt"
    },
    {
      "x": -2,
      "y": -1,
      "z": 3,
      "name": "Soil_Dirt"
    },
    {
      "x": -2,
      "y": 0,
      "z": 3,
      "name": "Soil_Grass"
    },
    {
      "x": -2,
      "y": 1,
      "z": 3,
      "name": "Empty"
    },
    {
      "x": -2,
      "y": 2,
      "z": 3,
      "name": "Empty"
    },
    {
      "x": -2,
      "y": 3,
      "z": 3,
      "name": "Empty"
    },
    {
      "x": -2,
      "y": 4,
      "z": 3,
      "name": "Empty"
    },
    {
      "x": -2,
      "y": 5,
      "z": 3,
      "name": "Empty"
    },
    {
      "x": -2,
      "y": 6,
      "z": 3,
      "name": "Empty"
    },
    {
      "x": -2,
      "y": 7,
      "z": 3,
      "name": "Wood_Softwood_Roof"
    },
    {
      "x": -2,
      "y": -4,
      "z": 4,
      "name": "Rock_Stone"
    },
    {
      "x": -2,
      "y": -3,
      "z": 4,
      "name": "Rock_Stone"
    },
    {
      "x": -2,
      "y": -2,
      "z": 4,
      "name": "Soil_Dirt"
    },
    {
      "x": -2,
      "y": -1,
      "z": 4,
      "name": "Soil_Dirt"
    },
    {
      "x": -2,
      "y": 0,
      "z": 4,
      "name": "Soil_Grass"
    },
    {
      "x": -2,
      "y": 1,
      "z": 4,
      "name": "Empty"
    },
    {
      "x": -2,
      "y": 2,
      "z": 4,
      "name": "Empty"
    },
    {
      "x": -2,
      "y": 3,
      "z": 4,
      "name": "Empty"
    },
    {
      "x": -2,
      "y": 4,
      "z": 4,
      "name": "Empty"
    },
    {
      "x": -2,
      "y": 5,
      "z": 4,
      "name": "Empty"
    },
    {
      "x": -2,
      "y": 6,
      "z": 4,
      "name": "Wood_Softwood_Roof"
    },
    {
      "x": -2,
      "y": -4,
      "z": 5,
      "name": "Rock_Stone"
    },
    {
      "x": -2,
      "y": -3,
      "z": 5,
      "name": "Rock_Stone"
    },
    {
      "x": -2,
      "y": -2,
      "z": 5,
      "name": "Soil_Dirt"
    },
    {
      "x": -2,
      "y": -1,
      "z": 5,
      "name": "Soil_Dirt"
    },
    {
      "x": -2,
      "y": 0,
      "z": 5,
      "name": "Soil_Grass"
    },
    {
      "x": -2,
      "y": 1,
      "z": 5,
      "name": "Empty"
    },
    {
      "x": -2,
      "y": 2,
      "z": 5,
      "name": "Empty"
    },
    {
      "x": -2,
      "y": 3,
      "z": 5,
      "name": "Empty"
    },
    {
      "x": -2,
      "y": 4,
      "z": 5,
      "name": "Empty"
    },
    {
      "x": -2,
      "y": 5,
      "z": 5,
      "name": "Wood_Softwood_Roof"
    },
    {
      "x": -2,
      "y": -4,
      "z": 6,
      "name": "Rock_Stone"
    },
    {
      "x": -2,
      "y": -3,
      "z": 6,
      "name": "Rock_Stone"
    },
    {
      "x": -2,
      "y": -2,
      "z": 6,
      "name": "Soil_Dirt"
    },
    {
      "x": -2,
      "y": -1,
      "z": 6,
      "name": "Soil_Dirt"
    },
    {
      "x": -2,
      "y": 0,
      "z": 6,
      "name": "Soil_Grass"
    },
    {
      "x": -2,
      "y": 1,
      "z": 6,
      "name": "Empty"
    },
    {
      "x": -2,
      "y": 2,
      "z": 6,
      "name": "Empty"
    },
    {
      "x": -2,
      "y": 3,
      "z": 6,
      "name": "Empty"
    },
    {
      "x": -2,
      "y": 4,
      "z": 6,
      "name": "Wood_Softwood_Roof"
    },
    {
      "x": -2,
      "y": -4,
      "z": 7,
      "name": "Rock_Stone"
    },
    {
      "x": -2,
      "y": -3,
      "z": 7,
      "name": "Rock_Stone"
    },
    {
      "x": -2,
      "y": -2,
      "z": 7,
      "name": "Soil_Dirt"
    },
    {
      "x": -2,
      "y": -1,
      "z": 7,
      "name": "Soil_Dirt"
    },
    {
      "x": -2,
      "y": 0,
      "z": 7,
      "name": "Soil_Grass"
    },
    {
      "x": -2,
      "y": 1,
      "z": 7,
      "name": "Empty"
    },
    {
      "x": -2,
      "y": 2,
      "z": 7,
      "name": "Empty"
    },
    {
      "x": -2,
      "y": 3,
      "z": 7,
      "name": "Empty"
    },
    {
      "x": -2,
      "y": 4,
      "z": 7,
      "name": "Empty"
    },
    {
      "x": -2,
      "y": -4,
      "z": 8,
      "name": "Rock_Stone"
    },
    {
      "x": -2,
      "y": -3,
      "z": 8,
      "name": "Rock_Stone"
    },
    {
      "x": -2,
      "y": -2,
      "z": 8,
      "name": "Soil_Dirt"
    },
    {
      "x": -2,
      "y": -1,
      "z": 8,
      "name": "Soil_Dirt"
    },
    {
      "x": -2,
      "y": 0,
      "z": 8,
      "name": "Soil_Grass"
    },
    {
      "x": -2,
      "y": 1,
      "z": 8,
      "name": "Plant_Flower_Common_Violet"
    },
    {
      "x": -2,
      "y": 2,
      "z": 8,
      "name": "Empty"
    },
    {
      "x": -2,
      "y": 3,
      "z": 8,
      "name": "Empty"
    },
    {
      "x": -2,
      "y": 4,
      "z": 8,
      "name": "Empty"
    },
    {
      "x": -2,
      "y": -4,
      "z": 9,
      "name": "Rock_Stone"
    },
    {
      "x": -2,
      "y": -3,
      "z": 9,
      "name": "Rock_Stone"
    },
    {
      "x": -2,
      "y": -2,
      "z": 9,
      "name": "Soil_Dirt"
    },
    {
      "x": -2,
      "y": -1,
      "z": 9,
      "name": "Soil_Dirt"
    },
    {
      "x": -2,
      "y": 0,
      "z": 9,
      "name": "Soil_Grass"
    },
    {
      "x": -2,
      "y": 1,
      "z": 9,
      "name": "Empty"
    },
    {
      "x": -2,
      "y": 2,
      "z": 9,
      "name": "Empty"
    },
    {
      "x": -2,
      "y": 3,
      "z": 9,
      "name": "Empty"
    },
    {
      "x": -2,
      "y": 4,
      "z": 9,
      "name": "Empty"
    },
    {
      "x": -2,
      "y": -4,
      "z": 10,
      "name": "Rock_Stone"
    },
    {
      "x": -2,
      "y": -3,
      "z": 10,
      "name": "Rock_Stone"
    },
    {
      "x": -2,
      "y": -2,
      "z": 10,
      "name": "Soil_Dirt"
    },
    {
      "x": -2,
      "y": -1,
      "z": 10,
      "name": "Soil_Dirt"
    },
    {
      "x": -2,
      "y": 0,
      "z": 10,
      "name": "Soil_Grass"
    },
    {
      "x": -2,
      "y": 1,
      "z": 10,
      "name": "Empty"
    },
    {
      "x": -2,
      "y": 2,
      "z": 10,
      "name": "Empty"
    },
    {
      "x": -2,
      "y": 3,
      "z": 10,
      "name": "Empty"
    },
    {
      "x": -2,
      "y": 4,
      "z": 10,
      "name": "Empty"
    },
    {
      "x": -2,
      "y": -4,
      "z": 11,
      "name": "Rock_Stone"
    },
    {
      "x": -2,
      "y": -3,
      "z": 11,
      "name": "Rock_Stone"
    },
    {
      "x": -2,
      "y": -2,
      "z": 11,
      "name": "Soil_Dirt"
    },
    {
      "x": -2,
      "y": -1,
      "z": 11,
      "name": "Soil_Dirt"
    },
    {
      "x": -2,
      "y": 0,
      "z": 11,
      "name": "Soil_Grass"
    },
    {
      "x": -2,
      "y": 1,
      "z": 11,
      "name": "Plant_Flower_Catnip"
    },
    {
      "x": -2,
      "y": 2,
      "z": 11,
      "name": "Empty"
    },
    {
      "x": -2,
      "y": 3,
      "z": 11,
      "name": "Empty"
    },
    {
      "x": -2,
      "y": 4,
      "z": 11,
      "name": "Empty"
    },
    {
      "x": -2,
      "y": -4,
      "z": 12,
      "name": "Rock_Stone"
    },
    {
      "x": -2,
      "y": -3,
      "z": 12,
      "name": "Rock_Stone"
    },
    {
      "x": -2,
      "y": -2,
      "z": 12,
      "name": "Soil_Dirt"
    },
    {
      "x": -2,
      "y": -1,
      "z": 12,
      "name": "Soil_Dirt"
    },
    {
      "x": -2,
      "y": 0,
      "z": 12,
      "name": "Soil_Grass"
    },
    {
      "x": -2,
      "y": 1,
      "z": 12,
      "name": "Plant_Flower_Catnip"
    },
    {
      "x": -2,
      "y": 2,
      "z": 12,
      "name": "Empty"
    },
    {
      "x": -2,
      "y": 3,
      "z": 12,
      "name": "Empty"
    },
    {
      "x": -2,
      "y": 4,
      "z": 12,
      "name": "Empty"
    },
    {
      "x": -2,
      "y": -3,
      "z": 13,
      "name": "Rock_Stone"
    },
    {
      "x": -2,
      "y": -2,
      "z": 13,
      "name": "Soil_Dirt"
    },
    {
      "x": -2,
      "y": -1,
      "z": 13,
      "name": "Soil_Dirt"
    },
    {
      "x": -2,
      "y": 0,
      "z": 13,
      "name": "Soil_Grass"
    },
    {
      "x": -2,
      "y": 1,
      "z": 13,
      "name": "Plant_Flower_Catnip"
    },
    {
      "x": -2,
      "y": 2,
      "z": 13,
      "name": "Empty"
    },
    {
      "x": -2,
      "y": 3,
      "z": 13,
      "name": "Empty"
    },
    {
      "x": -2,
      "y": 4,
      "z": 13,
      "name": "Empty"
    },
    {
      "x": -2,
      "y": -3,
      "z": 14,
      "name": "Rock_Stone"
    },
    {
      "x": -2,
      "y": -2,
      "z": 14,
      "name": "Soil_Dirt"
    },
    {
      "x": -2,
      "y": -1,
      "z": 14,
      "name": "Soil_Dirt"
    },
    {
      "x": -2,
      "y": 0,
      "z": 14,
      "name": "Soil_Grass"
    },
    {
      "x": -2,
      "y": 1,
      "z": 14,
      "name": "Wood_Softwood_Fence"
    },
    {
      "x": -2,
      "y": 2,
      "z": 14,
      "name": "Empty"
    },
    {
      "x": -2,
      "y": 3,
      "z": 14,
      "name": "Empty"
    },
    {
      "x": -2,
      "y": 4,
      "z": 14,
      "name": "Empty"
    },
    {
      "x": -2,
      "y": -2,
      "z": 15,
      "name": "Soil_Dirt"
    },
    {
      "x": -2,
      "y": -1,
      "z": 15,
      "name": "Soil_Dirt"
    },
    {
      "x": -2,
      "y": 0,
      "z": 15,
      "name": "Soil_Grass"
    },
    {
      "x": -2,
      "y": 1,
      "z": 15,
      "name": "Empty"
    },
    {
      "x": -2,
      "y": 2,
      "z": 15,
      "name": "Empty"
    },
    {
      "x": -2,
      "y": 3,
      "z": 15,
      "name": "Empty"
    },
    {
      "x": -2,
      "y": 4,
      "z": 15,
      "name": "Empty"
    },
    {
      "x": -1,
      "y": -2,
      "z": -4,
      "name": "Soil_Dirt"
    },
    {
      "x": -1,
      "y": -1,
      "z": -4,
      "name": "Soil_Dirt"
    },
    {
      "x": -1,
      "y": 0,
      "z": -4,
      "name": "Soil_Grass"
    },
    {
      "x": -1,
      "y": 1,
      "z": -4,
      "name": "Empty"
    },
    {
      "x": -1,
      "y": 2,
      "z": -4,
      "name": "Empty"
    },
    {
      "x": -1,
      "y": 3,
      "z": -4,
      "name": "Empty"
    },
    {
      "x": -1,
      "y": 4,
      "z": -4,
      "name": "Empty"
    },
    {
      "x": -1,
      "y": -3,
      "z": -3,
      "name": "Rock_Stone"
    },
    {
      "x": -1,
      "y": -2,
      "z": -3,
      "name": "Soil_Dirt"
    },
    {
      "x": -1,
      "y": -1,
      "z": -3,
      "name": "Soil_Dirt"
    },
    {
      "x": -1,
      "y": 0,
      "z": -3,
      "name": "Soil_Grass"
    },
    {
      "x": -1,
      "y": 1,
      "z": -3,
      "name": "Empty"
    },
    {
      "x": -1,
      "y": 2,
      "z": -3,
      "name": "Empty"
    },
    {
      "x": -1,
      "y": 3,
      "z": -3,
      "name": "Empty"
    },
    {
      "x": -1,
      "y": 4,
      "z": -3,
      "name": "Empty"
    },
    {
      "x": -1,
      "y": -4,
      "z": -2,
      "name": "Rock_Stone"
    },
    {
      "x": -1,
      "y": -3,
      "z": -2,
      "name": "Rock_Stone"
    },
    {
      "x": -1,
      "y": -2,
      "z": -2,
      "name": "Soil_Dirt"
    },
    {
      "x": -1,
      "y": -1,
      "z": -2,
      "name": "Soil_Dirt"
    },
    {
      "x": -1,
      "y": 0,
      "z": -2,
      "name": "Soil_Grass"
    },
    {
      "x": -1,
      "y": 1,
      "z": -2,
      "name": "Empty"
    },
    {
      "x": -1,
      "y": 2,
      "z": -2,
      "name": "Empty"
    },
    {
      "x": -1,
      "y": 3,
      "z": -2,
      "name": "Empty"
    },
    {
      "x": -1,
      "y": 4,
      "z": -2,
      "name": "Wood_Softwood_Roof",
      "rotation": 2
    },
    {
      "x": -1,
      "y": -4,
      "z": -1,
      "name": "Rock_Stone"
    },
    {
      "x": -1,
      "y": -3,
      "z": -1,
      "name": "Rock_Stone"
    },
    {
      "x": -1,
      "y": -2,
      "z": -1,
      "name": "Soil_Dirt"
    },
    {
      "x": -1,
      "y": -1,
      "z": -1,
      "name": "Soil_Dirt"
    },
    {
      "x": -1,
      "y": 0,
      "z": -1,
      "name": "Rock_Stone_Cobble"
    },
    {
      "x": -1,
      "y": 1,
      "z": -1,
      "name": "Wood_Softwood_Beam"
    },
    {
      "x": -1,
      "y": 2,
      "z": -1,
      "name": "Wood_Softwood_Beam"
    },
    {
      "x": -1,
      "y": 3,
      "z": -1,
      "name": "Wood_Softwood_Beam"
    },
    {
      "x": -1,
      "y": 4,
      "z": -1,
      "name": "Wood_Softwood_Beam"
    },
    {
      "x": -1,
      "y": 5,
      "z": -1,
      "name": "Wood_Softwood_Roof",
      "rotation": 2
    },
    {
      "x": -1,
      "y": -4,
      "z": 0,
      "name": "Rock_Stone"
    },
    {
      "x": -1,
      "y": -3,
      "z": 0,
      "name": "Rock_Stone"
    },
    {
      "x": -1,
      "y": -2,
      "z": 0,
      "name": "Soil_Dirt"
    },
    {
      "x": -1,
      "y": -1,
      "z": 0,
      "name": "Soil_Dirt"
    },
    {
      "x": -1,
      "y": 0,
      "z": 0,
      "name": "Rock_Stone_Cobble"
    },
    {
      "x": -1,
      "y": 1,
      "z": 0,
      "name": "Rock_Stone_Cobble"
    },
    {
      "x": -1,
      "y": 2,
      "z": 0,
      "name": "Wood_Softwood_Planks"
    },
    {
      "x": -1,
      "y": 3,
      "z": 0,
      "name": "Wood_Softwood_Planks"
    },
    {
      "x": -1,
      "y": 4,
      "z": 0,
      "name": "Wood_Softwood_Planks"
    },
    {
      "x": -1,
      "y": 5,
      "z": 0,
      "name": "Wood_Softwood_Planks"
    },
    {
      "x": -1,
      "y": 6,
      "z": 0,
      "name": "Wood_Softwood_Roof",
      "rotation": 2
    },
    {
      "x": -1,
      "y": -4,
      "z": 1,
      "name": "Rock_Stone"
    },
    {
      "x": -1,
      "y": -3,
      "z": 1,
      "name": "Rock_Stone"
    },
    {
      "x": -1,
      "y": -2,
      "z": 1,
      "name": "Soil_Dirt"
    },
    {
      "x": -1,
      "y": -1,
      "z": 1,
      "name": "Soil_Dirt"
    },
    {
      "x": -1,
      "y": 0,
      "z": 1,
      "name": "Rock_Stone_Cobble"
    },
    {
      "x": -1,
      "y": 1,
      "z": 1,
      "name": "Rock_Stone_Cobble"
    },
    {
      "x": -1,
      "y": 2,
      "z": 1,
      "name": "Wood_Softwood_Planks"
    },
    {
      "x": -1,
      "y": 3,
      "z": 1,
      "name": "Wood_Softwood_Planks"
    },
    {
      "x": -1,
      "y": 4,
      "z": 1,
      "name": "Wood_Softwood_Planks"
    },
    {
      "x": -1,
      "y": 5,
      "z": 1,
      "name": "Wood_Softwood_Planks"
    },
    {
      "x": -1,
      "y": 6,
      "z": 1,
      "name": "Wood_Softwood_Planks"
    },
    {
      "x": -1,
      "y": 7,
      "z": 1,
      "name": "Wood_Softwood_Roof",
      "rotation": 2
    },
    {
      "x": -1,
      "y": -4,
      "z": 2,
      "name": "Rock_Stone"
    },
    {
      "x": -1,
      "y": -3,
      "z": 2,
      "name": "Rock_Stone"
    },
    {
      "x": -1,
      "y": -2,
      "z": 2,
      "name": "Soil_Dirt"
    },
    {
      "x": -1,
      "y": -1,
      "z": 2,
      "name": "Soil_Dirt"
    },
    {
      "x": -1,
      "y": 0,
      "z": 2,
      "name": "Rock_Stone_Cobble"
    },
    {
      "x": -1,
      "y": 1,
      "z": 2,
      "name": "Rock_Stone_Cobble"
    },
    {
      "x": -1,
      "y": 2,
      "z": 2,
      "name": "Furniture_Village_Window",
      "rotation": 1
    },
    {
      "x": -1,
      "y": 3,
      "z": 2,
      "name": "Furniture_Village_Window",
      "rotation": 1
    },
    {
      "x": -1,
      "y": 4,
      "z": 2,
      "name": "Wood_Softwood_Planks"
    },
    {
      "x": -1,
      "y": 5,
      "z": 2,
      "name": "Wood_Softwood_Planks"
    },
    {
      "x": -1,
      "y": 6,
      "z": 2,
      "name": "Wood_Softwood_Planks"
    },
    {
      "x": -1,
      "y": 7,
      "z": 2,
      "name": "Wood_Softwood_Planks"
    },
    {
      "x": -1,
      "y": 8,
      "z": 2,
      "name": "*Wood_Softwood_Roof_State_Definitions_Topper"
    },
    {
      "x": -1,
      "y": -4,
      "z": 3,
      "name": "Rock_Stone"
    },
    {
      "x": -1,
      "y": -3,
      "z": 3,
      "name": "Rock_Stone"
    },
    {
      "x": -1,
      "y": -2,
      "z": 3,
      "name": "Soil_Dirt"
    },
    {
      "x": -1,
      "y": -1,
      "z": 3,
      "name": "Soil_Dirt"
    },
    {
      "x": -1,
      "y": 0,
      "z": 3,
      "name": "Rock_Stone_Cobble"
    },
    {
      "x": -1,
      "y": 1,
      "z": 3,
      "name": "Rock_Stone_Cobble"
    },
    {
      "x": -1,
      "y": 2,
      "z": 3,
      "name": "Wood_Softwood_Planks"
    },
    {
      "x": -1,
      "y": 3,
      "z": 3,
      "name": "Wood_Softwood_Planks"
    },
    {
      "x": -1,
      "y": 4,
      "z": 3,
      "name": "Wood_Softwood_Planks"
    },
    {
      "x": -1,
      "y": 5,
      "z": 3,
      "name": "Wood_Softwood_Planks"
    },
    {
      "x": -1,
      "y": 6,
      "z": 3,
      "name": "Wood_Softwood_Planks"
    },
    {
      "x": -1,
      "y": 7,
      "z": 3,
      "name": "Wood_Softwood_Roof"
    },
    {
      "x": -1,
      "y": -4,
      "z": 4,
      "name": "Rock_Stone"
    },
    {
      "x": -1,
      "y": -3,
      "z": 4,
      "name": "Rock_Stone"
    },
    {
      "x": -1,
      "y": -2,
      "z": 4,
      "name": "Soil_Dirt"
    },
    {
      "x": -1,
      "y": -1,
      "z": 4,
      "name": "Soil_Dirt"
    },
    {
      "x": -1,
      "y": 0,
      "z": 4,
      "name": "Rock_Stone_Cobble"
    },
    {
      "x": -1,
      "y": 1,
      "z": 4,
      "name": "Rock_Stone_Cobble"
    },
    {
      "x": -1,
      "y": 2,
      "z": 4,
      "name": "Wood_Softwood_Planks"
    },
    {
      "x": -1,
      "y": 3,
      "z": 4,
      "name": "Wood_Softwood_Planks"
    },
    {
      "x": -1,
      "y": 4,
      "z": 4,
      "name": "Wood_Softwood_Planks"
    },
    {
      "x": -1,
      "y": 5,
      "z": 4,
      "name": "Wood_Softwood_Planks"
    },
    {
      "x": -1,
      "y": 6,
      "z": 4,
      "name": "Wood_Softwood_Roof"
    },
    {
      "x": -1,
      "y": -4,
      "z": 5,
      "name": "Rock_Stone"
    },
    {
      "x": -1,
      "y": -3,
      "z": 5,
      "name": "Rock_Stone"
    },
    {
      "x": -1,
      "y": -2,
      "z": 5,
      "name": "Soil_Dirt"
    },
    {
      "x": -1,
      "y": -1,
      "z": 5,
      "name": "Soil_Dirt"
    },
    {
      "x": -1,
      "y": 0,
      "z": 5,
      "name": "Rock_Stone_Cobble"
    },
    {
      "x": -1,
      "y": 1,
      "z": 5,
      "name": "Wood_Softwood_Beam"
    },
    {
      "x": -1,
      "y": 2,
      "z": 5,
      "name": "Wood_Softwood_Beam"
    },
    {
      "x": -1,
      "y": 3,
      "z": 5,
      "name": "Wood_Softwood_Beam"
    },
    {
      "x": -1,
      "y": 4,
      "z": 5,
      "name": "Wood_Softwood_Beam"
    },
    {
      "x": -1,
      "y": 5,
      "z": 5,
      "name": "Wood_Softwood_Roof"
    },
    {
      "x": -1,
      "y": -4,
      "z": 6,
      "name": "Rock_Stone"
    },
    {
      "x": -1,
      "y": -3,
      "z": 6,
      "name": "Rock_Stone"
    },
    {
      "x": -1,
      "y": -2,
      "z": 6,
      "name": "Soil_Dirt"
    },
    {
      "x": -1,
      "y": -1,
      "z": 6,
      "name": "Soil_Dirt"
    },
    {
      "x": -1,
      "y": 0,
      "z": 6,
      "name": "Wood_Softwood_Planks"
    },
    {
      "x": -1,
      "y": 1,
      "z": 6,
      "name": "Empty"
    },
    {
      "x": -1,
      "y": 2,
      "z": 6,
      "name": "Empty"
    },
    {
      "x": -1,
      "y": 3,
      "z": 6,
      "name": "Empty"
    },
    {
      "x": -1,
      "y": 4,
      "z": 6,
      "name": "Wood_Softwood_Roof"
    },
    {
      "x": -1,
      "y": -4,
      "z": 7,
      "name": "Rock_Stone"
    },
    {
      "x": -1,
      "y": -3,
      "z": 7,
      "name": "Rock_Stone"
    },
    {
      "x": -1,
      "y": -2,
      "z": 7,
      "name": "Soil_Dirt"
    },
    {
      "x": -1,
      "y": -1,
      "z": 7,
      "name": "Soil_Dirt"
    },
    {
      "x": -1,
      "y": 0,
      "z": 7,
      "name": "Wood_Softwood_Planks"
    },
    {
      "x": -1,
      "y": 1,
      "z": 7,
      "name": "Deco_Lantern"
    },
    {
      "x": -1,
      "y": 2,
      "z": 7,
      "name": "Empty"
    },
    {
      "x": -1,
      "y": 3,
      "z": 7,
      "name": "Empty"
    },
    {
      "x": -1,
      "y": 4,
      "z": 7,
      "name": "Empty"
    },
    {
      "x": -1,
      "y": -4,
      "z": 8,
      "name": "Rock_Stone"
    },
    {
      "x": -1,
      "y": -3,
      "z": 8,
      "name": "Rock_Stone"
    },
    {
      "x": -1,
      "y": -2,
      "z": 8,
      "name": "Soil_Dirt"
    },
    {
      "x": -1,
      "y": -1,
      "z": 8,
      "name": "Soil_Dirt"
    },
    {
      "x": -1,
      "y": 0,
      "z": 8,
      "name": "Soil_Grass"
    },
    {
      "x": -1,
      "y": 1,
      "z": 8,
      "name": "Empty"
    },
    {
      "x": -1,
      "y": 2,
      "z": 8,
      "name": "Empty"
    },
    {
      "x": -1,
      "y": 3,
      "z": 8,
      "name": "Empty"
    },
    {
      "x": -1,
      "y": 4,
      "z": 8,
      "name": "Empty"
    },
    {
      "x": -1,
      "y": -4,
      "z": 9,
      "name": "Rock_Stone"
    },
    {
      "x": -1,
      "y": -3,
      "z": 9,
      "name": "Rock_Stone"
    },
    {
      "x": -1,
      "y": -2,
      "z": 9,
      "name": "Soil_Dirt"
    },
    {
      "x": -1,
      "y": -1,
      "z": 9,
      "name": "Soil_Dirt"
    },
    {
      "x": -1,
      "y": 0,
      "z": 9,
      "name": "Soil_Grass"
    },
    {
      "x": -1,
      "y": 1,
      "z": 9,
      "name": "Empty"
    },
    {
      "x": -1,
      "y": 2,
      "z": 9,
      "name": "Empty"
    },
    {
      "x": -1,
      "y": 3,
      "z": 9,
      "name": "Empty"
    },
    {
      "x": -1,
      "y": 4,
      "z": 9,
      "name": "Empty"
    },
    {
      "x": -1,
      "y": -4,
      "z": 10,
      "name": "Rock_Stone"
    },
    {
      "x": -1,
      "y": -3,
      "z": 10,
      "name": "Rock_Stone"
    },
    {
      "x": -1,
      "y": -2,
      "z": 10,
      "name": "Soil_Dirt"
    },
    {
      "x": -1,
      "y": -1,
      "z": 10,
      "name": "Soil_Dirt"
    },
    {
      "x": -1,
      "y": 0,
      "z": 10,
      "name": "Soil_Gravel"
    },
    {
      "x": -1,
      "y": 1,
      "z": 10,
      "name": "Empty"
    },
    {
      "x": -1,
      "y": 2,
      "z": 10,
      "name": "Empty"
    },
    {
      "x": -1,
      "y": 3,
      "z": 10,
      "name": "Empty"
    },
    {
      "x": -1,
      "y": 4,
      "z": 10,
      "name": "Empty"
    },
    {
      "x": -1,
      "y": -4,
      "z": 11,
      "name": "Rock_Stone"
    },
    {
      "x": -1,
      "y": -3,
      "z": 11,
      "name": "Rock_Stone"
    },
    {
      "x": -1,
      "y": -2,
      "z": 11,
      "name": "Soil_Dirt"
    },
    {
      "x": -1,
      "y": -1,
      "z": 11,
      "name": "Soil_Dirt"
    },
    {
      "x": -1,
      "y": 0,
      "z": 11,
      "name": "Soil_Grass"
    },
    {
      "x": -1,
      "y": 1,
      "z": 11,
      "name": "Empty"
    },
    {
      "x": -1,
      "y": 2,
      "z": 11,
      "name": "Empty"
    },
    {
      "x": -1,
      "y": 3,
      "z": 11,
      "name": "Empty"
    },
    {
      "x": -1,
      "y": 4,
      "z": 11,
      "name": "Empty"
    },
    {
      "x": -1,
      "y": -4,
      "z": 12,
      "name": "Rock_Stone"
    },
    {
      "x": -1,
      "y": -3,
      "z": 12,
      "name": "Rock_Stone"
    },
    {
      "x": -1,
      "y": -2,
      "z": 12,
      "name": "Soil_Dirt"
    },
    {
      "x": -1,
      "y": -1,
      "z": 12,
      "name": "Soil_Dirt"
    },
    {
      "x": -1,
      "y": 0,
      "z": 12,
      "name": "Soil_Grass"
    },
    {
      "x": -1,
      "y": 1,
      "z": 12,
      "name": "Plant_Flower_Catnip"
    },
    {
      "x": -1,
      "y": 2,
      "z": 12,
      "name": "Empty"
    },
    {
      "x": -1,
      "y": 3,
      "z": 12,
      "name": "Empty"
    },
    {
      "x": -1,
      "y": 4,
      "z": 12,
      "name": "Empty"
    },
    {
      "x": -1,
      "y": -4,
      "z": 13,
      "name": "Rock_Stone"
    },
    {
      "x": -1,
      "y": -3,
      "z": 13,
      "name": "Rock_Stone"
    },
    {
      "x": -1,
      "y": -2,
      "z": 13,
      "name": "Soil_Dirt"
    },
    {
      "x": -1,
      "y": -1,
      "z": 13,
      "name": "Soil_Dirt"
    },
    {
      "x": -1,
      "y": 0,
      "z": 13,
      "name": "Soil_Grass"
    },
    {
      "x": -1,
      "y": 1,
      "z": 13,
      "name": "Plant_Flower_Catnip"
    },
    {
      "x": -1,
      "y": 2,
      "z": 13,
      "name": "Empty"
    },
    {
      "x": -1,
      "y": 3,
      "z": 13,
      "name": "Empty"
    },
    {
      "x": -1,
      "y": 4,
      "z": 13,
      "name": "Empty"
    },
    {
      "x": -1,
      "y": -3,
      "z": 14,
      "name": "Rock_Stone"
    },
    {
      "x": -1,
      "y": -2,
      "z": 14,
      "name": "Soil_Dirt"
    },
    {
      "x": -1,
      "y": -1,
      "z": 14,
      "name": "Soil_Dirt"
    },
    {
      "x": -1,
      "y": 0,
      "z": 14,
      "name": "Soil_Grass"
    },
    {
      "x": -1,
      "y": 1,
      "z": 14,
      "name": "Wood_Softwood_Fence"
    },
    {
      "x": -1,
      "y": 2,
      "z": 14,
      "name": "Empty"
    },
    {
      "x": -1,
      "y": 3,
      "z": 14,
      "name": "Empty"
    },
    {
      "x": -1,
      "y": 4,
      "z": 14,
      "name": "Empty"
    },
    {
      "x": -1,
      "y": -2,
      "z": 15,
      "name": "Soil_Dirt"
    },
    {
      "x": -1,
      "y": -1,
      "z": 15,
      "name": "Soil_Dirt"
    },
    {
      "x": -1,
      "y": 0,
      "z": 15,
      "name": "Soil_Grass"
    },
    {
      "x": -1,
      "y": 1,
      "z": 15,
      "name": "Empty"
    },
    {
      "x": -1,
      "y": 2,
      "z": 15,
      "name": "Empty"
    },
    {
      "x": -1,
      "y": 3,
      "z": 15,
      "name": "Empty"
    },
    {
      "x": -1,
      "y": 4,
      "z": 15,
      "name": "Empty"
    },
    {
      "x": 0,
      "y": -2,
      "z": -4,
      "name": "Soil_Dirt"
    },
    {
      "x": 0,
      "y": -1,
      "z": -4,
      "name": "Soil_Dirt"
    },
    {
      "x": 0,
      "y": 0,
      "z": -4,
      "name": "Soil_Grass"
    },
    {
      "x": 0,
      "y": 1,
      "z": -4,
      "name": "Empty"
    },
    {
      "x": 0,
      "y": 2,
      "z": -4,
      "name": "Empty"
    },
    {
      "x": 0,
      "y": 3,
      "z": -4,
      "name": "Empty"
    },
    {
      "x": 0,
      "y": 4,
      "z": -4,
      "name": "Empty"
    },
    {
      "x": 0,
      "y": -3,
      "z": -3,
      "name": "Rock_Stone"
    },
    {
      "x": 0,
      "y": -2,
      "z": -3,
      "name": "Soil_Dirt"
    },
    {
      "x": 0,
      "y": -1,
      "z": -3,
      "name": "Soil_Dirt"
    },
    {
      "x": 0,
      "y": 0,
      "z": -3,
      "name": "Soil_Grass"
    },
    {
      "x": 0,
      "y": 1,
      "z": -3,
      "name": "Empty"
    },
    {
      "x": 0,
      "y": 2,
      "z": -3,
      "name": "Empty"
    },
    {
      "x": 0,
      "y": 3,
      "z": -3,
      "name": "Empty"
    },
    {
      "x": 0,
      "y": 4,
      "z": -3,
      "name": "Empty"
    },
    {
      "x": 0,
      "y": -4,
      "z": -2,
      "name": "Rock_Stone"
    },
    {
      "x": 0,
      "y": -3,
      "z": -2,
      "name": "Rock_Stone"
    },
    {
      "x": 0,
      "y": -2,
      "z": -2,
      "name": "Soil_Dirt"
    },
    {
      "x": 0,
      "y": -1,
      "z": -2,
      "name": "Soil_Dirt"
    },
    {
      "x": 0,
      "y": 0,
      "z": -2,
      "name": "Soil_Grass"
    },
    {
      "x": 0,
      "y": 1,
      "z": -2,
      "name": "Empty"
    },
    {
      "x": 0,
      "y": 2,
      "z": -2,
      "name": "Plant_Vine_Wall",
      "rotation": 2
    },
    {
      "x": 0,
      "y": 3,
      "z": -2,
      "name": "Plant_Vine_Wall",
      "rotation": 2
    },
    {
      "x": 0,
      "y": 4,
      "z": -2,
      "name": "Wood_Softwood_Roof",
      "rotation": 2
    },
    {
      "x": 0,
      "y": -4,
      "z": -1,
      "name": "Rock_Stone"
    },
    {
      "x": 0,
      "y": -3,
      "z": -1,
      "name": "Rock_Stone"
    },
    {
      "x": 0,
      "y": -2,
      "z": -1,
      "name": "Soil_Dirt"
    },
    {
      "x": 0,
      "y": -1,
      "z": -1,
      "name": "Soil_Dirt"
    },
    {
      "x": 0,
      "y": 0,
      "z": -1,
      "name": "Rock_Stone_Cobble"
    },
    {
      "x": 0,
      "y": 1,
      "z": -1,
      "name": "Rock_Stone_Cobble"
    },
    {
      "x": 0,
      "y": 2,
      "z": -1,
      "name": "Wood_Softwood_Planks"
    },
    {
      "x": 0,
      "y": 3,
      "z": -1,
      "name": "Wood_Softwood_Planks"
    },
    {
      "x": 0,
      "y": 4,
      "z": -1,
      "name": "Wood_Softwood_Planks"
    },
    {
      "x": 0,
      "y": 5,
      "z": -1,
      "name": "Wood_Softwood_Roof",
      "rotation": 2
    },
    {
      "x": 0,
      "y": -4,
      "z": 0,
      "name": "Rock_Stone"
    },
    {
      "x": 0,
      "y": -3,
      "z": 0,
      "name": "Rock_Stone"
    },
    {
      "x": 0,
      "y": -2,
      "z": 0,
      "name": "Soil_Dirt"
    },
    {
      "x": 0,
      "y": -1,
      "z": 0,
      "name": "Soil_Dirt"
    },
    {
      "x": 0,
      "y": 0,
      "z": 0,
      "name": "Wood_Softwood_Planks"
    },
    {
      "x": 0,
      "y": 1,
      "z": 0,
      "name": "Deco_Lantern"
    },
    {
      "x": 0,
      "y": 2,
      "z": 0,
      "name": "Empty"
    },
    {
      "x": 0,
      "y": 3,
      "z": 0,
      "name": "Empty"
    },
    {
      "x": 0,
      "y": 4,
      "z": 0,
      "name": "Empty"
    },
    {
      "x": 0,
      "y": 5,
      "z": 0,
      "name": "Empty"
    },
    {
      "x": 0,
      "y": 6,
      "z": 0,
      "name": "Wood_Softwood_Roof",
      "rotation": 2
    },
    {
      "x": 0,
      "y": -4,
      "z": 1,
      "name": "Rock_Stone"
    },
    {
      "x": 0,
      "y": -3,
      "z": 1,
      "name": "Rock_Stone"
    },
    {
      "x": 0,
      "y": -2,
      "z": 1,
      "name": "Soil_Dirt"
    },
    {
      "x": 0,
      "y": -1,
      "z": 1,
      "name": "Soil_Dirt"
    },
    {
      "x": 0,
      "y": 0,
      "z": 1,
      "name": "Wood_Softwood_Planks"
    },
    {
      "x": 0,
      "y": 1,
      "z": 1,
      "name": "Empty"
    },
    {
      "x": 0,
      "y": 2,
      "z": 1,
      "name": "Empty"
    },
    {
      "x": 0,
      "y": 3,
      "z": 1,
      "name": "Furniture_Village_Painting_1x1",
      "rotation": 1
    },
    {
      "x": 0,
      "y": 4,
      "z": 1,
      "name": "Empty"
    },
    {
      "x": 0,
      "y": 5,
      "z": 1,
      "name": "Empty"
    },
    {
      "x": 0,
      "y": 6,
      "z": 1,
      "name": "Empty"
    },
    {
      "x": 0,
      "y": 7,
      "z": 1,
      "name": "Wood_Softwood_Roof",
      "rotation": 2
    },
    {
      "x": 0,
      "y": -4,
      "z": 2,
      "name": "Rock_Stone"
    },
    {
      "x": 0,
      "y": -3,
      "z": 2,
      "name": "Rock_Stone"
    },
    {
      "x": 0,
      "y": -2,
      "z": 2,
      "name": "Soil_Dirt"
    },
    {
      "x": 0,
      "y": -1,
      "z": 2,
      "name": "Soil_Dirt"
    },
    {
      "x": 0,
      "y": 0,
      "z": 2,
      "name": "Wood_Softwood_Planks"
    },
    {
      "x": 0,
      "y": 1,
      "z": 2,
      "name": "Cat_Box",
      "rotation": 1
    },
    {
      "x": 0,
      "y": 2,
      "z": 2,
      "name": "Empty"
    },
    {
      "x": 0,
      "y": 3,
      "z": 2,
      "name": "Empty"
    },
    {
      "x": 0,
      "y": 4,
      "z": 2,
      "name": "Empty"
    },
    {
      "x": 0,
      "y": 5,
      "z": 2,
      "name": "Empty"
    },
    {
      "x": 0,
      "y": 6,
      "z": 2,
      "name": "Empty"
    },
    {
      "x": 0,
      "y": 7,
      "z": 2,
      "name": "Empty"
    },
    {
      "x": 0,
      "y": 8,
      "z": 2,
      "name": "*Wood_Softwood_Roof_State_Definitions_Topper"
    },
    {
      "x": 0,
      "y": -4,
      "z": 3,
      "name": "Rock_Stone"
    },
    {
      "x": 0,
      "y": -3,
      "z": 3,
      "name": "Rock_Stone"
    },
    {
      "x": 0,
      "y": -2,
      "z": 3,
      "name": "Soil_Dirt"
    },
    {
      "x": 0,
      "y": -1,
      "z": 3,
      "name": "Soil_Dirt"
    },
    {
      "x": 0,
      "y": 0,
      "z": 3,
      "name": "Wood_Softwood_Planks"
    },
    {
      "x": 0,
      "y": 1,
      "z": 3,
      "name": "Empty"
    },
    {
      "x": 0,
      "y": 2,
      "z": 3,
      "name": "Empty"
    },
    {
      "x": 0,
      "y": 3,
      "z": 3,
      "name": "Empty"
    },
    {
      "x": 0,
      "y": 4,
      "z": 3,
      "name": "Empty"
    },
    {
      "x": 0,
      "y": 5,
      "z": 3,
      "name": "Empty"
    },
    {
      "x": 0,
      "y": 6,
      "z": 3,
      "name": "Empty"
    },
    {
      "x": 0,
      "y": 7,
      "z": 3,
      "name": "Wood_Softwood_Roof"
    },
    {
      "x": 0,
      "y": -4,
      "z": 4,
      "name": "Rock_Stone"
    },
    {
      "x": 0,
      "y": -3,
      "z": 4,
      "name": "Rock_Stone"
    },
    {
      "x": 0,
      "y": -2,
      "z": 4,
      "name": "Soil_Dirt"
    },
    {
      "x": 0,
      "y": -1,
      "z": 4,
      "name": "Soil_Dirt"
    },
    {
      "x": 0,
      "y": 0,
      "z": 4,
      "name": "Wood_Softwood_Planks"
    },
    {
      "x": 0,
      "y": 1,
      "z": 4,
      "name": "Furniture_Village_Chest_Small",
      "rotation": 1,
      "components": {
        "Components": {
          "ItemContainerBlock": {
            "ItemContainer": {
              "Id": "Simple",
              "Capacity": 18,
              "Items": {
                "0": {
                  "Id": "Cat_Yarn_Ball",
                  "Quantity": 1,
                  "Durability": 0.0,
                  "MaxDurability": 0.0,
                  "OverrideDroppedItemAnimation": false
                },
                "1": {
                  "Id": "Cat_Yarn_Ball",
                  "Quantity": 1,
                  "Durability": 0.0,
                  "MaxDurability": 0.0,
                  "OverrideDroppedItemAnimation": false
                },
                "2": {
                  "Id": "Cat_Yarn_Ball",
                  "Quantity": 1,
                  "Durability": 0.0,
                  "MaxDurability": 0.0,
                  "OverrideDroppedItemAnimation": false
                },
                "3": {
                  "Id": "Cat_Teaser_Toy",
                  "Quantity": 1,
                  "Durability": 0.0,
                  "MaxDurability": 0.0,
                  "OverrideDroppedItemAnimation": false
                },
                "4": {
                  "Id": "AlecsCats_Command_Item",
                  "Quantity": 1,
                  "Durability": 0.0,
                  "MaxDurability": 0.0,
                  "OverrideDroppedItemAnimation": false
                },
                "5": {
                  "Id": "Food_Fish_Raw",
                  "Quantity": 20,
                  "Durability": 0.0,
                  "MaxDurability": 0.0,
                  "OverrideDroppedItemAnimation": false
                },
                "6": {
                  "Id": "Container_Bucket",
                  "Quantity": 1,
                  "Durability": 0.0,
                  "MaxDurability": 0.0,
                  "OverrideDroppedItemAnimation": false
                }
              }
            },
            "Capacity": 18
          }
        }
      }
    },
    {
      "x": 0,
      "y": 2,
      "z": 4,
      "name": "Empty"
    },
    {
      "x": 0,
      "y": 3,
      "z": 4,
      "name": "Empty"
    },
    {
      "x": 0,
      "y": 4,
      "z": 4,
      "name": "Empty"
    },
    {
      "x": 0,
      "y": 5,
      "z": 4,
      "name": "Empty"
    },
    {
      "x": 0,
      "y": 6,
      "z": 4,
      "name": "Wood_Softwood_Roof"
    },
    {
      "x": 0,
      "y": -4,
      "z": 5,
      "name": "Rock_Stone"
    },
    {
      "x": 0,
      "y": -3,
      "z": 5,
      "name": "Rock_Stone"
    },
    {
      "x": 0,
      "y": -2,
      "z": 5,
      "name": "Soil_Dirt"
    },
    {
      "x": 0,
      "y": -1,
      "z": 5,
      "name": "Soil_Dirt"
    },
    {
      "x": 0,
      "y": 0,
      "z": 5,
      "name": "Wood_Softwood_Planks"
    },
    {
      "x": 0,
      "y": 1,
      "z": 5,
      "name": "Empty"
    },
    {
      "x": 0,
      "y": 2,
      "z": 5,
      "name": "Empty"
    },
    {
      "x": 0,
      "y": 3,
      "z": 5,
      "name": "Empty"
    },
    {
      "x": 0,
      "y": 4,
      "z": 5,
      "name": "Wood_Softwood_Beam",
      "rotation": 5
    },
    {
      "x": 0,
      "y": 5,
      "z": 5,
      "name": "Wood_Softwood_Roof"
    },
    {
      "x": 0,
      "y": -4,
      "z": 6,
      "name": "Rock_Stone"
    },
    {
      "x": 0,
      "y": -3,
      "z": 6,
      "name": "Rock_Stone"
    },
    {
      "x": 0,
      "y": -2,
      "z": 6,
      "name": "Soil_Dirt"
    },
    {
      "x": 0,
      "y": -1,
      "z": 6,
      "name": "Soil_Dirt"
    },
    {
      "x": 0,
      "y": 0,
      "z": 6,
      "name": "Wood_Softwood_Planks"
    },
    {
      "x": 0,
      "y": 1,
      "z": 6,
      "name": "Cat_Bed"
    },
    {
      "x": 0,
      "y": 2,
      "z": 6,
      "name": "Empty"
    },
    {
      "x": 0,
      "y": 3,
      "z": 6,
      "name": "Empty"
    },
    {
      "x": 0,
      "y": 4,
      "z": 6,
      "name": "Wood_Softwood_Roof"
    },
    {
      "x": 0,
      "y": -4,
      "z": 7,
      "name": "Rock_Stone"
    },
    {
      "x": 0,
      "y": -3,
      "z": 7,
      "name": "Rock_Stone"
    },
    {
      "x": 0,
      "y": -2,
      "z": 7,
      "name": "Soil_Dirt"
    },
    {
      "x": 0,
      "y": -1,
      "z": 7,
      "name": "Soil_Dirt"
    },
    {
      "x": 0,
      "y": 0,
      "z": 7,
      "name": "Wood_Softwood_Planks"
    },
    {
      "x": 0,
      "y": 1,
      "z": 7,
      "name": "Empty"
    },
    {
      "x": 0,
      "y": 2,
      "z": 7,
      "name": "Empty"
    },
    {
      "x": 0,
      "y": 3,
      "z": 7,
      "name": "Empty"
    },
    {
      "x": 0,
      "y": 4,
      "z": 7,
      "name": "Empty"
    },
    {
      "x": 0,
      "y": -4,
      "z": 8,
      "name": "Rock_Stone"
    },
    {
      "x": 0,
      "y": -3,
      "z": 8,
      "name": "Rock_Stone"
    },
    {
      "x": 0,
      "y": -2,
      "z": 8,
      "name": "Soil_Dirt"
    },
    {
      "x": 0,
      "y": -1,
      "z": 8,
      "name": "Soil_Dirt"
    },
    {
      "x": 0,
      "y": 0,
      "z": 8,
      "name": "Soil_Grass"
    },
    {
      "x": 0,
      "y": 1,
      "z": 8,
      "name": "Empty"
    },
    {
      "x": 0,
      "y": 2,
      "z": 8,
      "name": "Empty"
    },
    {
      "x": 0,
      "y": 3,
      "z": 8,
      "name": "Empty"
    },
    {
      "x": 0,
      "y": 4,
      "z": 8,
      "name": "Empty"
    },
    {
      "x": 0,
      "y": -4,
      "z": 9,
      "name": "Rock_Stone"
    },
    {
      "x": 0,
      "y": -3,
      "z": 9,
      "name": "Rock_Stone"
    },
    {
      "x": 0,
      "y": -2,
      "z": 9,
      "name": "Soil_Dirt"
    },
    {
      "x": 0,
      "y": -1,
      "z": 9,
      "name": "Soil_Dirt"
    },
    {
      "x": 0,
      "y": 0,
      "z": 9,
      "name": "Soil_Grass"
    },
    {
      "x": 0,
      "y": 1,
      "z": 9,
      "name": "Empty"
    },
    {
      "x": 0,
      "y": 2,
      "z": 9,
      "name": "Empty"
    },
    {
      "x": 0,
      "y": 3,
      "z": 9,
      "name": "Empty"
    },
    {
      "x": 0,
      "y": 4,
      "z": 9,
      "name": "Empty"
    },
    {
      "x": 0,
      "y": -4,
      "z": 10,
      "name": "Rock_Stone"
    },
    {
      "x": 0,
      "y": -3,
      "z": 10,
      "name": "Rock_Stone"
    },
    {
      "x": 0,
      "y": -2,
      "z": 10,
      "name": "Soil_Dirt"
    },
    {
      "x": 0,
      "y": -1,
      "z": 10,
      "name": "Soil_Dirt"
    },
    {
      "x": 0,
      "y": 0,
      "z": 10,
      "name": "Empty"
    },
    {
      "x": 0,
      "y": 1,
      "z": 10,
      "name": "Empty"
    },
    {
      "x": 0,
      "y": 2,
      "z": 10,
      "name": "Empty"
    },
    {
      "x": 0,
      "y": 3,
      "z": 10,
      "name": "Empty"
    },
    {
      "x": 0,
      "y": 4,
      "z": 10,
      "name": "Empty"
    },
    {
      "x": 0,
      "y": -4,
      "z": 11,
      "name": "Rock_Stone"
    },
    {
      "x": 0,
      "y": -3,
      "z": 11,
      "name": "Rock_Stone"
    },
    {
      "x": 0,
      "y": -2,
      "z": 11,
      "name": "Soil_Dirt"
    },
    {
      "x": 0,
      "y": -1,
      "z": 11,
      "name": "Soil_Dirt"
    },
    {
      "x": 0,
      "y": 0,
      "z": 11,
      "name": "Empty"
    },
    {
      "x": 0,
      "y": 1,
      "z": 11,
      "name": "Empty"
    },
    {
      "x": 0,
      "y": 2,
      "z": 11,
      "name": "Empty"
    },
    {
      "x": 0,
      "y": 3,
      "z": 11,
      "name": "Empty"
    },
    {
      "x": 0,
      "y": 4,
      "z": 11,
      "name": "Empty"
    },
    {
      "x": 0,
      "y": -4,
      "z": 12,
      "name": "Rock_Stone"
    },
    {
      "x": 0,
      "y": -3,
      "z": 12,
      "name": "Rock_Stone"
    },
    {
      "x": 0,
      "y": -2,
      "z": 12,
      "name": "Soil_Dirt"
    },
    {
      "x": 0,
      "y": -1,
      "z": 12,
      "name": "Soil_Dirt"
    },
    {
      "x": 0,
      "y": 0,
      "z": 12,
      "name": "Soil_Gravel"
    },
    {
      "x": 0,
      "y": 1,
      "z": 12,
      "name": "Empty"
    },
    {
      "x": 0,
      "y": 2,
      "z": 12,
      "name": "Empty"
    },
    {
      "x": 0,
      "y": 3,
      "z": 12,
      "name": "Empty"
    },
    {
      "x": 0,
      "y": 4,
      "z": 12,
      "name": "Empty"
    },
    {
      "x": 0,
      "y": -4,
      "z": 13,
      "name": "Rock_Stone"
    },
    {
      "x": 0,
      "y": -3,
      "z": 13,
      "name": "Rock_Stone"
    },
    {
      "x": 0,
      "y": -2,
      "z": 13,
      "name": "Soil_Dirt"
    },
    {
      "x": 0,
      "y": -1,
      "z": 13,
      "name": "Soil_Dirt"
    },
    {
      "x": 0,
      "y": 0,
      "z": 13,
      "name": "Soil_Grass"
    },
    {
      "x": 0,
      "y": 1,
      "z": 13,
      "name": "Plant_Flower_Catnip"
    },
    {
      "x": 0,
      "y": 2,
      "z": 13,
      "name": "Empty"
    },
    {
      "x": 0,
      "y": 3,
      "z": 13,
      "name": "Empty"
    },
    {
      "x": 0,
      "y": 4,
      "z": 13,
      "name": "Empty"
    },
    {
      "x": 0,
      "y": -3,
      "z": 14,
      "name": "Rock_Stone"
    },
    {
      "x": 0,
      "y": -2,
      "z": 14,
      "name": "Soil_Dirt"
    },
    {
      "x": 0,
      "y": -1,
      "z": 14,
      "name": "Soil_Dirt"
    },
    {
      "x": 0,
      "y": 0,
      "z": 14,
      "name": "Soil_Grass"
    },
    {
      "x": 0,
      "y": 1,
      "z": 14,
      "name": "Wood_Softwood_Fence"
    },
    {
      "x": 0,
      "y": 2,
      "z": 14,
      "name": "Empty"
    },
    {
      "x": 0,
      "y": 3,
      "z": 14,
      "name": "Empty"
    },
    {
      "x": 0,
      "y": 4,
      "z": 14,
      "name": "Empty"
    },
    {
      "x": 0,
      "y": -2,
      "z": 15,
      "name": "Soil_Dirt"
    },
    {
      "x": 0,
      "y": -1,
      "z": 15,
      "name": "Soil_Dirt"
    },
    {
      "x": 0,
      "y": 0,
      "z": 15,
      "name": "Soil_Grass"
    },
    {
      "x": 0,
      "y": 1,
      "z": 15,
      "name": "Empty"
    },
    {
      "x": 0,
      "y": 2,
      "z": 15,
      "name": "Empty"
    },
    {
      "x": 0,
      "y": 3,
      "z": 15,
      "name": "Empty"
    },
    {
      "x": 0,
      "y": 4,
      "z": 15,
      "name": "Empty"
    },
    {
      "x": 1,
      "y": -2,
      "z": -4,
      "name": "Soil_Dirt"
    },
    {
      "x": 1,
      "y": -1,
      "z": -4,
      "name": "Soil_Dirt"
    },
    {
      "x": 1,
      "y": 0,
      "z": -4,
      "name": "Soil_Grass"
    },
    {
      "x": 1,
      "y": 1,
      "z": -4,
      "name": "Empty"
    },
    {
      "x": 1,
      "y": 2,
      "z": -4,
      "name": "Empty"
    },
    {
      "x": 1,
      "y": 3,
      "z": -4,
      "name": "Empty"
    },
    {
      "x": 1,
      "y": 4,
      "z": -4,
      "name": "Empty"
    },
    {
      "x": 1,
      "y": -3,
      "z": -3,
      "name": "Rock_Stone"
    },
    {
      "x": 1,
      "y": -2,
      "z": -3,
      "name": "Soil_Dirt"
    },
    {
      "x": 1,
      "y": -1,
      "z": -3,
      "name": "Soil_Dirt"
    },
    {
      "x": 1,
      "y": 0,
      "z": -3,
      "name": "Soil_Grass"
    },
    {
      "x": 1,
      "y": 1,
      "z": -3,
      "name": "Empty"
    },
    {
      "x": 1,
      "y": 2,
      "z": -3,
      "name": "Empty"
    },
    {
      "x": 1,
      "y": 3,
      "z": -3,
      "name": "Empty"
    },
    {
      "x": 1,
      "y": 4,
      "z": -3,
      "name": "Empty"
    },
    {
      "x": 1,
      "y": -4,
      "z": -2,
      "name": "Rock_Stone"
    },
    {
      "x": 1,
      "y": -3,
      "z": -2,
      "name": "Rock_Stone"
    },
    {
      "x": 1,
      "y": -2,
      "z": -2,
      "name": "Soil_Dirt"
    },
    {
      "x": 1,
      "y": -1,
      "z": -2,
      "name": "Soil_Dirt"
    },
    {
      "x": 1,
      "y": 0,
      "z": -2,
      "name": "Soil_Grass"
    },
    {
      "x": 1,
      "y": 1,
      "z": -2,
      "name": "Empty"
    },
    {
      "x": 1,
      "y": 2,
      "z": -2,
      "name": "Empty"
    },
    {
      "x": 1,
      "y": 3,
      "z": -2,
      "name": "Empty"
    },
    {
      "x": 1,
      "y": 4,
      "z": -2,
      "name": "Wood_Softwood_Roof",
      "rotation": 2
    },
    {
      "x": 1,
      "y": -4,
      "z": -1,
      "name": "Rock_Stone"
    },
    {
      "x": 1,
      "y": -3,
      "z": -1,
      "name": "Rock_Stone"
    },
    {
      "x": 1,
      "y": -2,
      "z": -1,
      "name": "Soil_Dirt"
    },
    {
      "x": 1,
      "y": -1,
      "z": -1,
      "name": "Soil_Dirt"
    },
    {
      "x": 1,
      "y": 0,
      "z": -1,
      "name": "Rock_Stone_Cobble"
    },
    {
      "x": 1,
      "y": 1,
      "z": -1,
      "name": "Rock_Stone_Cobble"
    },
    {
      "x": 1,
      "y": 2,
      "z": -1,
      "name": "Wood_Softwood_Planks"
    },
    {
      "x": 1,
      "y": 3,
      "z": -1,
      "name": "Wood_Softwood_Planks"
    },
    {
      "x": 1,
      "y": 4,
      "z": -1,
      "name": "Wood_Softwood_Planks"
    },
    {
      "x": 1,
      "y": 5,
      "z": -1,
      "name": "Wood_Softwood_Roof",
      "rotation": 2
    },
    {
      "x": 1,
      "y": -4,
      "z": 0,
      "name": "Rock_Stone"
    },
    {
      "x": 1,
      "y": -3,
      "z": 0,
      "name": "Rock_Stone"
    },
    {
      "x": 1,
      "y": -2,
      "z": 0,
      "name": "Soil_Dirt"
    },
    {
      "x": 1,
      "y": -1,
      "z": 0,
      "name": "Soil_Dirt"
    },
    {
      "x": 1,
      "y": 0,
      "z": 0,
      "name": "Wood_Softwood_Planks"
    },
    {
      "x": 1,
      "y": 1,
      "z": 0,
      "name": "Cat_Tower"
    },
    {
      "x": 1,
      "y": 2,
      "z": 0,
      "name": "Cat_Tower",
      "filler": 1024
    },
    {
      "x": 1,
      "y": 3,
      "z": 0,
      "name": "Empty"
    },
    {
      "x": 1,
      "y": 4,
      "z": 0,
      "name": "Empty"
    },
    {
      "x": 1,
      "y": 5,
      "z": 0,
      "name": "Empty"
    },
    {
      "x": 1,
      "y": 6,
      "z": 0,
      "name": "Wood_Softwood_Roof",
      "rotation": 2
    },
    {
      "x": 1,
      "y": -4,
      "z": 1,
      "name": "Rock_Stone"
    },
    {
      "x": 1,
      "y": -3,
      "z": 1,
      "name": "Rock_Stone"
    },
    {
      "x": 1,
      "y": -2,
      "z": 1,
      "name": "Soil_Dirt"
    },
    {
      "x": 1,
      "y": -1,
      "z": 1,
      "name": "Soil_Dirt"
    },
    {
      "x": 1,
      "y": 0,
      "z": 1,
      "name": "Wood_Softwood_Planks"
    },
    {
      "x": 1,
      "y": 1,
      "z": 1,
      "name": "Empty"
    },
    {
      "x": 1,
      "y": 2,
      "z": 1,
      "name": "Empty"
    },
    {
      "x": 1,
      "y": 3,
      "z": 1,
      "name": "Empty"
    },
    {
      "x": 1,
      "y": 4,
      "z": 1,
      "name": "Empty"
    },
    {
      "x": 1,
      "y": 5,
      "z": 1,
      "name": "Empty"
    },
    {
      "x": 1,
      "y": 6,
      "z": 1,
      "name": "Empty"
    },
    {
      "x": 1,
      "y": 7,
      "z": 1,
      "name": "Wood_Softwood_Roof",
      "rotation": 2
    },
    {
      "x": 1,
      "y": -4,
      "z": 2,
      "name": "Rock_Stone"
    },
    {
      "x": 1,
      "y": -3,
      "z": 2,
      "name": "Rock_Stone"
    },
    {
      "x": 1,
      "y": -2,
      "z": 2,
      "name": "Soil_Dirt"
    },
    {
      "x": 1,
      "y": -1,
      "z": 2,
      "name": "Soil_Dirt"
    },
    {
      "x": 1,
      "y": 0,
      "z": 2,
      "name": "Wood_Softwood_Planks"
    },
    {
      "x": 1,
      "y": 1,
      "z": 2,
      "name": "Empty"
    },
    {
      "x": 1,
      "y": 2,
      "z": 2,
      "name": "Empty"
    },
    {
      "x": 1,
      "y": 3,
      "z": 2,
      "name": "Empty"
    },
    {
      "x": 1,
      "y": 4,
      "z": 2,
      "name": "Empty"
    },
    {
      "x": 1,
      "y": 5,
      "z": 2,
      "name": "Empty"
    },
    {
      "x": 1,
      "y": 6,
      "z": 2,
      "name": "Empty"
    },
    {
      "x": 1,
      "y": 7,
      "z": 2,
      "name": "Empty"
    },
    {
      "x": 1,
      "y": 8,
      "z": 2,
      "name": "*Wood_Softwood_Roof_State_Definitions_Topper"
    },
    {
      "x": 1,
      "y": -4,
      "z": 3,
      "name": "Rock_Stone"
    },
    {
      "x": 1,
      "y": -3,
      "z": 3,
      "name": "Rock_Stone"
    },
    {
      "x": 1,
      "y": -2,
      "z": 3,
      "name": "Soil_Dirt"
    },
    {
      "x": 1,
      "y": -1,
      "z": 3,
      "name": "Soil_Dirt"
    },
    {
      "x": 1,
      "y": 0,
      "z": 3,
      "name": "Wood_Softwood_Planks"
    },
    {
      "x": 1,
      "y": 1,
      "z": 3,
      "name": "Empty"
    },
    {
      "x": 1,
      "y": 2,
      "z": 3,
      "name": "Empty"
    },
    {
      "x": 1,
      "y": 3,
      "z": 3,
      "name": "Empty"
    },
    {
      "x": 1,
      "y": 4,
      "z": 3,
      "name": "Empty"
    },
    {
      "x": 1,
      "y": 5,
      "z": 3,
      "name": "Empty"
    },
    {
      "x": 1,
      "y": 6,
      "z": 3,
      "name": "Empty"
    },
    {
      "x": 1,
      "y": 7,
      "z": 3,
      "name": "Wood_Softwood_Roof"
    },
    {
      "x": 1,
      "y": -4,
      "z": 4,
      "name": "Rock_Stone"
    },
    {
      "x": 1,
      "y": -3,
      "z": 4,
      "name": "Rock_Stone"
    },
    {
      "x": 1,
      "y": -2,
      "z": 4,
      "name": "Soil_Dirt"
    },
    {
      "x": 1,
      "y": -1,
      "z": 4,
      "name": "Soil_Dirt"
    },
    {
      "x": 1,
      "y": 0,
      "z": 4,
      "name": "Wood_Softwood_Planks"
    },
    {
      "x": 1,
      "y": 1,
      "z": 4,
      "name": "Empty"
    },
    {
      "x": 1,
      "y": 2,
      "z": 4,
      "name": "Empty"
    },
    {
      "x": 1,
      "y": 3,
      "z": 4,
      "name": "Empty"
    },
    {
      "x": 1,
      "y": 4,
      "z": 4,
      "name": "Empty"
    },
    {
      "x": 1,
      "y": 5,
      "z": 4,
      "name": "Empty"
    },
    {
      "x": 1,
      "y": 6,
      "z": 4,
      "name": "Wood_Softwood_Roof"
    },
    {
      "x": 1,
      "y": -4,
      "z": 5,
      "name": "Rock_Stone"
    },
    {
      "x": 1,
      "y": -3,
      "z": 5,
      "name": "Rock_Stone"
    },
    {
      "x": 1,
      "y": -2,
      "z": 5,
      "name": "Soil_Dirt"
    },
    {
      "x": 1,
      "y": -1,
      "z": 5,
      "name": "Soil_Dirt"
    },
    {
      "x": 1,
      "y": 0,
      "z": 5,
      "name": "Wood_Softwood_Planks"
    },
    {
      "x": 1,
      "y": 1,
      "z": 5,
      "name": "Empty"
    },
    {
      "x": 1,
      "y": 2,
      "z": 5,
      "name": "Empty"
    },
    {
      "x": 1,
      "y": 3,
      "z": 5,
      "name": "Empty"
    },
    {
      "x": 1,
      "y": 4,
      "z": 5,
      "name": "Wood_Softwood_Beam",
      "rotation": 5
    },
    {
      "x": 1,
      "y": 5,
      "z": 5,
      "name": "Wood_Softwood_Roof"
    },
    {
      "x": 1,
      "y": -4,
      "z": 6,
      "name": "Rock_Stone"
    },
    {
      "x": 1,
      "y": -3,
      "z": 6,
      "name": "Rock_Stone"
    },
    {
      "x": 1,
      "y": -2,
      "z": 6,
      "name": "Soil_Dirt"
    },
    {
      "x": 1,
      "y": -1,
      "z": 6,
      "name": "Soil_Dirt"
    },
    {
      "x": 1,
      "y": 0,
      "z": 6,
      "name": "Wood_Softwood_Planks"
    },
    {
      "x": 1,
      "y": 1,
      "z": 6,
      "name": "Empty"
    },
    {
      "x": 1,
      "y": 2,
      "z": 6,
      "name": "Empty"
    },
    {
      "x": 1,
      "y": 3,
      "z": 6,
      "name": "Empty"
    },
    {
      "x": 1,
      "y": 4,
      "z": 6,
      "name": "Wood_Softwood_Roof"
    },
    {
      "x": 1,
      "y": -4,
      "z": 7,
      "name": "Rock_Stone"
    },
    {
      "x": 1,
      "y": -3,
      "z": 7,
      "name": "Rock_Stone"
    },
    {
      "x": 1,
      "y": -2,
      "z": 7,
      "name": "Soil_Dirt"
    },
    {
      "x": 1,
      "y": -1,
      "z": 7,
      "name": "Soil_Dirt"
    },
    {
      "x": 1,
      "y": 0,
      "z": 7,
      "name": "Wood_Softwood_Planks"
    },
    {
      "x": 1,
      "y": 1,
      "z": 7,
      "name": "Empty"
    },
    {
      "x": 1,
      "y": 2,
      "z": 7,
      "name": "Empty"
    },
    {
      "x": 1,
      "y": 3,
      "z": 7,
      "name": "Empty"
    },
    {
      "x": 1,
      "y": 4,
      "z": 7,
      "name": "Empty"
    },
    {
      "x": 1,
      "y": -4,
      "z": 8,
      "name": "Rock_Stone"
    },
    {
      "x": 1,
      "y": -3,
      "z": 8,
      "name": "Rock_Stone"
    },
    {
      "x": 1,
      "y": -2,
      "z": 8,
      "name": "Soil_Dirt"
    },
    {
      "x": 1,
      "y": -1,
      "z": 8,
      "name": "Soil_Dirt"
    },
    {
      "x": 1,
      "y": 0,
      "z": 8,
      "name": "Soil_Grass"
    },
    {
      "x": 1,
      "y": 1,
      "z": 8,
      "name": "Empty"
    },
    {
      "x": 1,
      "y": 2,
      "z": 8,
      "name": "Empty"
    },
    {
      "x": 1,
      "y": 3,
      "z": 8,
      "name": "Empty"
    },
    {
      "x": 1,
      "y": 4,
      "z": 8,
      "name": "Empty"
    },
    {
      "x": 1,
      "y": -4,
      "z": 9,
      "name": "Rock_Stone"
    },
    {
      "x": 1,
      "y": -3,
      "z": 9,
      "name": "Rock_Stone"
    },
    {
      "x": 1,
      "y": -2,
      "z": 9,
      "name": "Soil_Dirt"
    },
    {
      "x": 1,
      "y": -1,
      "z": 9,
      "name": "Soil_Dirt"
    },
    {
      "x": 1,
      "y": 0,
      "z": 9,
      "name": "Soil_Gravel"
    },
    {
      "x": 1,
      "y": 1,
      "z": 9,
      "name": "Empty"
    },
    {
      "x": 1,
      "y": 2,
      "z": 9,
      "name": "Empty"
    },
    {
      "x": 1,
      "y": 3,
      "z": 9,
      "name": "Empty"
    },
    {
      "x": 1,
      "y": 4,
      "z": 9,
      "name": "Empty"
    },
    {
      "x": 1,
      "y": -4,
      "z": 10,
      "name": "Rock_Stone"
    },
    {
      "x": 1,
      "y": -3,
      "z": 10,
      "name": "Rock_Stone"
    },
    {
      "x": 1,
      "y": -2,
      "z": 10,
      "name": "Soil_Dirt"
    },
    {
      "x": 1,
      "y": -1,
      "z": 10,
      "name": "Soil_Dirt"
    },
    {
      "x": 1,
      "y": 0,
      "z": 10,
      "name": "Empty"
    },
    {
      "x": 1,
      "y": 1,
      "z": 10,
      "name": "Empty"
    },
    {
      "x": 1,
      "y": 2,
      "z": 10,
      "name": "Empty"
    },
    {
      "x": 1,
      "y": 3,
      "z": 10,
      "name": "Empty"
    },
    {
      "x": 1,
      "y": 4,
      "z": 10,
      "name": "Empty"
    },
    {
      "x": 1,
      "y": -4,
      "z": 11,
      "name": "Rock_Stone"
    },
    {
      "x": 1,
      "y": -3,
      "z": 11,
      "name": "Rock_Stone"
    },
    {
      "x": 1,
      "y": -2,
      "z": 11,
      "name": "Soil_Dirt"
    },
    {
      "x": 1,
      "y": -1,
      "z": 11,
      "name": "Soil_Dirt"
    },
    {
      "x": 1,
      "y": 0,
      "z": 11,
      "name": "Empty"
    },
    {
      "x": 1,
      "y": 1,
      "z": 11,
      "name": "Empty"
    },
    {
      "x": 1,
      "y": 2,
      "z": 11,
      "name": "Empty"
    },
    {
      "x": 1,
      "y": 3,
      "z": 11,
      "name": "Empty"
    },
    {
      "x": 1,
      "y": 4,
      "z": 11,
      "name": "Empty"
    },
    {
      "x": 1,
      "y": -4,
      "z": 12,
      "name": "Rock_Stone"
    },
    {
      "x": 1,
      "y": -3,
      "z": 12,
      "name": "Rock_Stone"
    },
    {
      "x": 1,
      "y": -2,
      "z": 12,
      "name": "Soil_Dirt"
    },
    {
      "x": 1,
      "y": -1,
      "z": 12,
      "name": "Soil_Dirt"
    },
    {
      "x": 1,
      "y": 0,
      "z": 12,
      "name": "Soil_Grass"
    },
    {
      "x": 1,
      "y": 1,
      "z": 12,
      "name": "Empty"
    },
    {
      "x": 1,
      "y": 2,
      "z": 12,
      "name": "Empty"
    },
    {
      "x": 1,
      "y": 3,
      "z": 12,
      "name": "Empty"
    },
    {
      "x": 1,
      "y": 4,
      "z": 12,
      "name": "Empty"
    },
    {
      "x": 1,
      "y": -4,
      "z": 13,
      "name": "Rock_Stone"
    },
    {
      "x": 1,
      "y": -3,
      "z": 13,
      "name": "Rock_Stone"
    },
    {
      "x": 1,
      "y": -2,
      "z": 13,
      "name": "Soil_Dirt"
    },
    {
      "x": 1,
      "y": -1,
      "z": 13,
      "name": "Soil_Dirt"
    },
    {
      "x": 1,
      "y": 0,
      "z": 13,
      "name": "Soil_Grass"
    },
    {
      "x": 1,
      "y": 1,
      "z": 13,
      "name": "Empty"
    },
    {
      "x": 1,
      "y": 2,
      "z": 13,
      "name": "Empty"
    },
    {
      "x": 1,
      "y": 3,
      "z": 13,
      "name": "Empty"
    },
    {
      "x": 1,
      "y": 4,
      "z": 13,
      "name": "Empty"
    },
    {
      "x": 1,
      "y": -3,
      "z": 14,
      "name": "Rock_Stone"
    },
    {
      "x": 1,
      "y": -2,
      "z": 14,
      "name": "Soil_Dirt"
    },
    {
      "x": 1,
      "y": -1,
      "z": 14,
      "name": "Soil_Dirt"
    },
    {
      "x": 1,
      "y": 0,
      "z": 14,
      "name": "Soil_Grass"
    },
    {
      "x": 1,
      "y": 1,
      "z": 14,
      "name": "Wood_Softwood_Fence"
    },
    {
      "x": 1,
      "y": 2,
      "z": 14,
      "name": "Empty"
    },
    {
      "x": 1,
      "y": 3,
      "z": 14,
      "name": "Empty"
    },
    {
      "x": 1,
      "y": 4,
      "z": 14,
      "name": "Empty"
    },
    {
      "x": 1,
      "y": -2,
      "z": 15,
      "name": "Soil_Dirt"
    },
    {
      "x": 1,
      "y": -1,
      "z": 15,
      "name": "Soil_Dirt"
    },
    {
      "x": 1,
      "y": 0,
      "z": 15,
      "name": "Soil_Grass"
    },
    {
      "x": 1,
      "y": 1,
      "z": 15,
      "name": "Empty"
    },
    {
      "x": 1,
      "y": 2,
      "z": 15,
      "name": "Empty"
    },
    {
      "x": 1,
      "y": 3,
      "z": 15,
      "name": "Empty"
    },
    {
      "x": 1,
      "y": 4,
      "z": 15,
      "name": "Empty"
    },
    {
      "x": 2,
      "y": -2,
      "z": -4,
      "name": "Soil_Dirt"
    },
